<?xml version="1.0"?>
<robot name="iCub">
  <link name="root_link">
    <inertial>
      <mass value="2.6629877504874604"/>
      <origin xyz="0.0035506047153235866 -1.495920436742083e-4 0.024519005956610603" rpy="0 -0 0"/>
      <inertia ixx="0.004618821158702131" ixy="2.1225922968713773e-6" ixz="1.2101663560375619e-4" iyy="0.0041897728838428076" iyz="1.2411456346931601e-5" izz="0.0026241207587260743"/>
    </inertial>
    <visual>
      <origin xyz="0 0 0" rpy="0 -0 0"/>
      <geometry>
        <mesh filename="package://iRonCub-Mk3/iRonCub/meshes/obj/sim_icub3_root_link.obj" scale="0.001 0.001 0.001"/>
      </geometry>
      <material name="">
        <color rgba="0.5 0.5 0.5 1"/>
      </material>
    </visual>
    <collision>
      <origin xyz="0 0 0" rpy="0 -0 0"/>
      <geometry>
        <mesh filename="package://iRonCub-Mk3/iRonCub/meshes/obj/sim_icub3_root_link.obj" scale="0.001 0.001 0.001"/>
      </geometry>
      <material name="">
        <color rgba="0.5 0.5 0.5 1"/>
      </material>
    </collision>
  </link>
  <joint name="l_hip_pitch" type="revolute">
    <origin xyz="0.021599999999999838 0.0404500000000001 5.551115123125783e-17" rpy="-2.772152493573635e-17 3.287426415778874e-15 -2.9480469897414543e-16"/>
    <axis xyz="2.621035289673297e-16 -1 -2.7721621189479363e-17"/>
    <parent link="root_link"/>
    <child link="l_hip_1"/>
    <limit lower="-0.7853981633974483" upper="2.007128639793479" effort="1e+9" velocity="1e+9"/>
    <dynamics damping="2" friction="0"/>
  </joint>
  <link name="l_hip_1">
    <inertial>
      <mass value="2.2348449454352943"/>
      <origin xyz="-0.004074069440706474 0.028123280846168733 -7.243260242532079e-4" rpy="0 -0 0"/>
      <inertia ixx="0.0021916451360404444" ixy="6.47725598985244e-5" ixz="-1.3159623138316396e-5" iyy="0.0026839116171697534" iyz="-2.8677556023102584e-6" izz="0.0024425758894069567"/>
    </inertial>
    <visual>
      <origin xyz="0 0 0" rpy="0 -0 0"/>
      <geometry>
        <mesh filename="package://iRonCub-Mk3/iRonCub/meshes/obj/sim_icub3_l_hip_1.obj" scale="0.001 0.001 0.001"/>
      </geometry>
      <material name="">
        <color rgba="0.5 0.5 0.5 1"/>
      </material>
    </visual>
    <collision>
      <origin xyz="0 0 0" rpy="0 -0 0"/>
      <geometry>
        <mesh filename="package://iRonCub-Mk3/iRonCub/meshes/obj/sim_icub3_l_hip_1.obj" scale="0.001 0.001 0.001"/>
      </geometry>
      <material name="">
        <color rgba="0.5 0.5 0.5 1"/>
      </material>
    </collision>
  </link>
  <joint name="r_hip_pitch" type="revolute">
    <origin xyz="0.021599999999999755 -0.040549999999999864 1.6653345369377348e-16" rpy="-1.110561606349201e-16 5.28941969589271e-15 8.233098219243898e-17"/>
    <axis xyz="-2.5657452984070894e-16 -1 -1.1105625688866552e-16"/>
    <parent link="root_link"/>
    <child link="r_hip_1"/>
    <limit lower="-0.7853981633974483" upper="2.007128639793479" effort="1e+9" velocity="1e+9"/>
    <dynamics damping="2" friction="0"/>
  </joint>
  <link name="r_hip_1">
    <inertial>
      <mass value="2.236088342871916"/>
      <origin xyz="-0.004106487245625876 -0.028109839642556263 -8.358564041556216e-4" rpy="0 -0 0"/>
      <inertia ixx="0.002274050572883787" ixy="-6.646311453920132e-5" ixz="-1.6231225606391436e-5" iyy="0.002767314809687873" iyz="6.667480643867252e-6" izz="0.0024473940588690597"/>
    </inertial>
    <visual>
      <origin xyz="0 0 0" rpy="0 -0 0"/>
      <geometry>
        <mesh filename="package://iRonCub-Mk3/iRonCub/meshes/obj/sim_icub3_r_hip_1.obj" scale="0.001 0.001 0.001"/>
      </geometry>
      <material name="">
        <color rgba="0.5 0.5 0.5 1"/>
      </material>
    </visual>
    <collision>
      <origin xyz="0 0 0" rpy="0 -0 0"/>
      <geometry>
        <mesh filename="package://iRonCub-Mk3/iRonCub/meshes/obj/sim_icub3_r_hip_1.obj" scale="0.001 0.001 0.001"/>
      </geometry>
      <material name="">
        <color rgba="0.5 0.5 0.5 1"/>
      </material>
    </collision>
  </link>
  <joint name="torso_roll" type="revolute">
    <origin xyz="-3.026147803572561e-17 -4.999999999994841e-5 0.060500000000000054" rpy="-1.3601050333223173e-31 -5.551115123125783e-16 1.0865009219729226e-20"/>
    <axis xyz="-1 1.339518362819463e-16 1.2577495698321518e-15"/>
    <parent link="root_link"/>
    <child link="torso_1"/>
    <limit lower="-0.4014257279586958" upper="0.4014257279586958" effort="1e+9" velocity="1e+9"/>
    <dynamics damping="2" friction="0"/>
  </joint>
  <link name="torso_1">
    <inertial>
      <mass value="1.7568435600410703"/>
      <origin xyz="-0.008004199855839647 3.5130276364068173e-4 0.05194481095906714" rpy="0 -0 0"/>
      <inertia ixx="0.002704001065354341" ixy="-1.132401714304464e-6" ixz="-3.328239693456031e-4" iyy="0.0035179814878016314" iyz="4.672304187426514e-6" izz="0.0021296132468488324"/>
    </inertial>
    <visual>
      <origin xyz="0 0 0" rpy="0 -0 0"/>
      <geometry>
        <mesh filename="package://iRonCub-Mk3/iRonCub/meshes/obj/sim_icub3_torso_1.obj" scale="0.001 0.001 0.001"/>
      </geometry>
      <material name="">
        <color rgba="0.5 0.5 0.5 1"/>
      </material>
    </visual>
    <collision>
      <origin xyz="0 0 0" rpy="0 -0 0"/>
      <geometry>
        <mesh filename="package://iRonCub-Mk3/iRonCub/meshes/obj/sim_icub3_torso_1.obj" scale="0.001 0.001 0.001"/>
      </geometry>
      <material name="">
        <color rgba="0.5 0.5 0.5 1"/>
      </material>
    </collision>
  </link>
  <joint name="torso_pitch" type="revolute">
    <origin xyz="-6.67283601706106e-18 4.999999999996938e-5 0.07250000000000004" rpy="1.1102239871625957e-16 -3.3306690738754686e-16 -2.4501412044503564e-16"/>
    <axis xyz="-1.1102155323940791e-16 1 5.872997965345691e-16"/>
    <parent link="torso_1"/>
    <child link="torso_2"/>
    <limit lower="-0.3141592653589793" upper="0.7853981633974483" effort="1e+9" velocity="1e+9"/>
    <dynamics damping="2" friction="0"/>
  </joint>
  <link name="torso_2">
    <inertial>
      <mass value="0.7973007881979116"/>
      <origin xyz="0.0013193526698886456 0.0033219209736745463 0.026808073537901152" rpy="0 -0 0"/>
      <inertia ixx="0.0015101133308138724" ixy="3.6652548120564313e-6" ixz="-1.1177457987947623e-5" iyy="8.38212922542086e-4" iyz="7.46112208314757e-5" izz="0.001252038772346624"/>
    </inertial>
    <visual>
      <origin xyz="0 0 0" rpy="0 -0 0"/>
      <geometry>
        <mesh filename="package://iRonCub-Mk3/iRonCub/meshes/obj/sim_icub3_torso_2.obj" scale="0.001 0.001 0.001"/>
      </geometry>
      <material name="">
        <color rgba="0.5 0.5 0.5 1"/>
      </material>
    </visual>
    <collision>
      <origin xyz="0 0 0" rpy="0 -0 0"/>
      <geometry>
        <mesh filename="package://iRonCub-Mk3/iRonCub/meshes/obj/sim_icub3_torso_2.obj" scale="0.001 0.001 0.001"/>
      </geometry>
      <material name="">
        <color rgba="0.5 0.5 0.5 1"/>
      </material>
    </collision>
  </link>
  <joint name="torso_yaw" type="revolute">
    <origin xyz="2.1594264454155578e-17 5.885646208236616e-20 0.06446999999999999" rpy="-1.2321137764617832e-22 -1.1102242644158516e-16 -1.1102291848647704e-16"/>
    <axis xyz="-1.1101976037066927e-16 -5.988494954094898e-22 -1"/>
    <parent link="torso_2"/>
    <child link="chest"/>
    <limit lower="-0.7504915783575618" upper="0.7504915783575618" effort="1e+9" velocity="1e+9"/>
    <dynamics damping="2" friction="0"/>
  </joint>
  <link name="chest">
    <inertial>
      <mass value="7.74"/>
      <origin xyz="-0.012264267678138503 -2.0913721363379232e-4 0.06226272346884485" rpy="0 -0 0"/>
      <inertia ixx="0.035385363760700186" ixy="1.013992893017689e-4" ixz="-3.314932732026085e-5" iyy="0.029180876419389323" iyz="-1.1584760630466694e-4" izz="0.026523881613475565"/>
    </inertial>
    <visual>
      <origin xyz="0 0 0" rpy="0 -0 0"/>
      <geometry>
        <mesh filename="package://iRonCub-Mk3/iRonCub/meshes/obj/sim_icub3_chest.obj" scale="0.001 0.001 0.001"/>
      </geometry>
      <material name="">
        <color rgba="0.5 0.5 0.5 1"/>
      </material>
    </visual>
    <collision>
      <origin xyz="0 0 0" rpy="0 -0 0"/>
      <geometry>
        <mesh filename="package://iRonCub-Mk3/iRonCub/meshes/obj/sim_icub3_chest.obj" scale="0.001 0.001 0.001"/>
      </geometry>
      <material name="">
        <color rgba="0.5 0.5 0.5 1"/>
      </material>
    </collision>
  </link>
  <joint name="l_shoulder_pitch" type="revolute">
    <origin xyz="-0.020835110809513314 0.03974230787756868 0.10520337684251443" rpy="0.2532615634587303 1.1174434452692061e-10 -0.2617993877702263"/>
    <axis xyz="1.263954599823144e-16 1.0000000000000002 8.326672684688674e-17"/>
    <parent link="chest"/>
    <child link="l_shoulder_1"/>
    <limit lower="-3.0543261909900767" upper="0.3490658503988659" effort="1e+9" velocity="1e+9"/>
    <dynamics damping="2" friction="0"/>
  </joint>
  <link name="l_shoulder_1">
    <inertial>
      <mass value="0.8132882020978611"/>
      <origin xyz="1.6763217616769938e-4 0.08722563487559233 4.5089836424971885e-4" rpy="0 -0 0"/>
      <inertia ixx="0.0010920704289372717" ixy="3.3147674586490156e-6" ixz="2.0613407982031135e-6" iyy="3.219464350160181e-4" iyz="8.620367613797824e-6" izz="0.0010688702418839013"/>
    </inertial>
    <visual>
      <origin xyz="0 0 0" rpy="0 -0 0"/>
      <geometry>
        <mesh filename="package://iRonCub-Mk3/iRonCub/meshes/obj/sim_icub3_l_shoulder_1.obj" scale="0.001 0.001 0.001"/>
      </geometry>
      <material name="">
        <color rgba="0.5 0.5 0.5 1"/>
      </material>
    </visual>
    <collision>
      <origin xyz="0 0 0" rpy="0 -0 0"/>
      <geometry>
        <mesh filename="package://iRonCub-Mk3/iRonCub/meshes/obj/sim_icub3_l_shoulder_1.obj" scale="0.001 0.001 0.001"/>
      </geometry>
      <material name="">
        <color rgba="0.5 0.5 0.5 1"/>
      </material>
    </collision>
  </link>
  <joint name="r_shoulder_pitch" type="revolute">
    <origin xyz="-0.020835110809513314 -0.039742307877568765 0.10520337684251439" rpy="-0.2532615634587295 -1.8146566163866544e-16 0.2617993877991491"/>
    <axis xyz="9.330933250829091e-17 1.0000000000000002 -1.3877787807814457e-16"/>
    <parent link="chest"/>
    <child link="r_shoulder_1"/>
    <limit lower="-3.0543261909900767" upper="0.3490658503988659" effort="1e+9" velocity="1e+9"/>
    <dynamics damping="2" friction="0"/>
  </joint>
  <link name="r_shoulder_1">
    <inertial>
      <mass value="0.813839698711106"/>
      <origin xyz="1.6751126444148473e-4 -0.08721732535454527 4.507358666717004e-4" rpy="0 -0 0"/>
      <inertia ixx="0.0010922544669281558" ixy="-3.3231897035781045e-6" ixz="2.0732314773585944e-6" iyy="3.220216908963962e-4" iyz="-8.601724518799334e-6" izz="0.0010690080572466924"/>
    </inertial>
    <visual>
      <origin xyz="0 0 0" rpy="0 -0 0"/>
      <geometry>
        <mesh filename="package://iRonCub-Mk3/iRonCub/meshes/obj/sim_icub3_r_shoulder_1.obj" scale="0.001 0.001 0.001"/>
      </geometry>
      <material name="">
        <color rgba="0.5 0.5 0.5 1"/>
      </material>
    </visual>
    <collision>
      <origin xyz="0 0 0" rpy="0 -0 0"/>
      <geometry>
        <mesh filename="package://iRonCub-Mk3/iRonCub/meshes/obj/sim_icub3_r_shoulder_1.obj" scale="0.001 0.001 0.001"/>
      </geometry>
      <material name="">
        <color rgba="0.5 0.5 0.5 1"/>
      </material>
    </collision>
  </link>
  <joint name="jetpack" type="fixed">
    <origin xyz="-0.14499 -1.2999999999999988e-4 0.14541848765202772" rpy="1.2324731707866316e-32 9.625374400280887e-23 -1.5707963267948966"/>
    <parent link="chest"/>
    <child link="chest_jetpack"/>
  </joint>
  <link name="chest_jetpack">
    <inertial>
      <mass value="4.53"/>
      <origin xyz="-2.7239450875089056e-5 -0.0183358897647658 0.03425005290417793" rpy="0 -0 0"/>
      <inertia ixx="0.03167862147049015" ixy="2.2387098838732457e-5" ixz="-1.8898492015038172e-5" iyy="0.04284692384150374" iyz="0.009152748442320655" izz="0.04386588919109599"/>
    </inertial>
    <visual>
      <origin xyz="0 0 0" rpy="0 -0 0"/>
      <geometry>
        <mesh filename="package://iRonCub-Mk3/iRonCub/meshes/obj/sim_sea_3_jetpack.obj" scale="0.001 0.001 0.001"/>
      </geometry>
      <material name="">
        <color rgba="0.5 0.5 0.5 1"/>
      </material>
    </visual>
    <collision>
      <origin xyz="0 0 0" rpy="0 -0 0"/>
      <geometry>
        <mesh filename="package://iRonCub-Mk3/iRonCub/meshes/obj/sim_sea_3_jetpack.obj" scale="0.001 0.001 0.001"/>
      </geometry>
      <material name="">
        <color rgba="0.5 0.5 0.5 1"/>
      </material>
    </collision>
  </link>
  <joint name="neck_fixed_joint" type="fixed">
    <origin xyz="-0.0037884876520276793 1.1965149394276545e-19 0.1653" rpy="9.625374400280887e-23 -1.2324731707866316e-32 0"/>
    <parent link="chest"/>
    <child link="neck_1"/>
  </joint>
  <link name="neck_1">
    <inertial>
      <mass value="0.36603901400113703"/>
      <origin xyz="-0.0020740120862148275 3.5078633042914743e-4 0.031440537702076166" rpy="0 -0 0"/>
      <inertia ixx="2.874394158609982e-4" ixy="1.4976245677733992e-5" ixz="-5.678672052682316e-6" iyy="1.779437729417396e-4" iyz="-8.84609090159286e-6" izz="2.707162209259165e-4"/>
    </inertial>
    <visual>
      <origin xyz="0 0 0" rpy="0 -0 0"/>
      <geometry>
        <mesh filename="package://iRonCub-Mk3/iRonCub/meshes/obj/sim_head_neck_1.obj" scale="0.001 0.001 0.001"/>
      </geometry>
      <material name="">
        <color rgba="0.5 0.5 0.5 1"/>
      </material>
    </visual>
    <collision>
      <origin xyz="0 0 0" rpy="0 -0 0"/>
      <geometry>
        <mesh filename="package://iRonCub-Mk3/iRonCub/meshes/obj/sim_head_neck_1.obj" scale="0.001 0.001 0.001"/>
      </geometry>
      <material name="">
        <color rgba="0.5 0.5 0.5 1"/>
      </material>
    </collision>
  </link>
  <joint name="neck_pitch" type="revolute">
    <origin xyz="0.008650000000000001 1.6878364870223099e-6 0.049000000000000016" rpy="2.2204460492503082e-16 6.217249061879946e-15 1.8981965531880597e-30"/>
    <axis xyz="8.725115797153111e-32 -1 -9.730044485478919e-17"/>
    <parent link="neck_1"/>
    <child link="neck_2"/>
    <limit lower="-0.5235987755982988" upper="0.3839724354387525" effort="1e+9" velocity="1e+9"/>
    <dynamics damping="2" friction="0"/>
  </joint>
  <link name="neck_2">
    <inertial>
      <mass value="0.12554863591935564"/>
      <origin xyz="-0.006375600971249117 3.6309318120735294e-5 0.006597619464620752" rpy="0 -0 0"/>
      <inertia ixx="4.74184174153568e-5" ixy="-9.99576304411619e-8" ixz="9.392992936400923e-6" iyy="4.056869190094087e-5" iyz="5.8960139089129976e-8" izz="3.8662828755239135e-5"/>
    </inertial>
    <visual>
      <origin xyz="0 0 0" rpy="0 -0 0"/>
      <geometry>
        <mesh filename="package://iRonCub-Mk3/iRonCub/meshes/obj/sim_head_neck_2.obj" scale="0.001 0.001 0.001"/>
      </geometry>
      <material name="">
        <color rgba="0.5 0.5 0.5 1"/>
      </material>
    </visual>
    <collision>
      <origin xyz="0 0 0" rpy="0 -0 0"/>
      <geometry>
        <mesh filename="package://iRonCub-Mk3/iRonCub/meshes/obj/sim_head_neck_2.obj" scale="0.001 0.001 0.001"/>
      </geometry>
      <material name="">
        <color rgba="0.5 0.5 0.5 1"/>
      </material>
    </collision>
  </link>
  <joint name="neck_roll" type="revolute">
    <origin xyz="1.734723475976807e-18 5.389247126905486e-18 0.00950000000000005" rpy="7.143872767384513e-16 -3.33066907387547e-16 -1.1102230246251556e-16"/>
    <axis xyz="1 -1.1438332919722405e-17 -3.3306690738754676e-16"/>
    <parent link="neck_2"/>
    <child link="neck_3"/>
    <limit lower="-0.3490658503988659" upper="0.3490658503988659" effort="1e+9" velocity="1e+9"/>
    <dynamics damping="2" friction="0"/>
  </joint>
  <link name="neck_3">
    <inertial>
      <mass value="0.19013309992818875"/>
      <origin xyz="0.001265402264172368 -8.218822143861296e-5 0.03610933685405018" rpy="0 -0 0"/>
      <inertia ixx="1.1070277075925195e-4" ixy="3.723051703316207e-7" ixz="1.0316180753871673e-5" iyy="1.237711284683706e-4" iyz="-5.418855164604395e-7" izz="4.128068824031633e-5"/>
    </inertial>
    <visual>
      <origin xyz="0 0 0" rpy="0 -0 0"/>
      <geometry>
        <mesh filename="package://iRonCub-Mk3/iRonCub/meshes/obj/sim_head_neck_3.obj" scale="0.001 0.001 0.001"/>
      </geometry>
      <material name="">
        <color rgba="0.5 0.5 0.5 1"/>
      </material>
    </visual>
    <collision>
      <origin xyz="0 0 0" rpy="0 -0 0"/>
      <geometry>
        <mesh filename="package://iRonCub-Mk3/iRonCub/meshes/obj/sim_head_neck_3.obj" scale="0.001 0.001 0.001"/>
      </geometry>
      <material name="">
        <color rgba="0.5 0.5 0.5 1"/>
      </material>
    </collision>
  </link>
  <joint name="neck_yaw" type="revolute">
    <origin xyz="-8.673617379884035e-19 4.965942411515149e-18 0.06914999999999992" rpy="-7.514452136555288e-16 -9.159339953157524e-16 3.4450928483976655e-16"/>
    <axis xyz="9.159339953157524e-16 -7.514452136555287e-16 0.9999999999999999"/>
    <parent link="neck_3"/>
    <child link="head"/>
    <limit lower="-0.7853981633974483" upper="0.7853981633974483" effort="1e+9" velocity="1e+9"/>
    <dynamics damping="2" friction="0"/>
  </joint>
  <link name="head">
    <inertial>
      <mass value="1.492979865988926"/>
      <origin xyz="-0.0010717321288527294 -0.002581852571624899 0.021357021858803255" rpy="0 -0 0"/>
      <inertia ixx="0.004525255660901079" ixy="2.0173563472947957e-4" ixz="-2.6715191506428566e-4" iyy="0.007528802171092508" iyz="1.052956946869648e-4" izz="0.007326386290126885"/>
    </inertial>
    <visual>
      <origin xyz="0 0 0" rpy="0 -0 0"/>
      <geometry>
        <mesh filename="package://iRonCub-Mk3/iRonCub/meshes/obj/sim_head_head.obj" scale="0.001 0.001 0.001"/>
      </geometry>
      <material name="">
        <color rgba="0.5 0.5 0.5 1"/>
      </material>
    </visual>
    <collision>
      <origin xyz="0 0 0" rpy="0 -0 0"/>
      <geometry>
        <mesh filename="package://iRonCub-Mk3/iRonCub/meshes/obj/sim_head_head.obj" scale="0.001 0.001 0.001"/>
      </geometry>
      <material name="">
        <color rgba="0.5 0.5 0.5 1"/>
      </material>
    </collision>
  </link>
  <joint name="l_jet_ft_sensor" type="fixed">
    <origin xyz="-0.29983115371327507 0.015279475722973251 -0.17995519310613678" rpy="-2.879793265790644 -4.1835689553950905e-16 1.5707963267948966"/>
    <parent link="chest_jetpack"/>
    <child link="chest_l_jet_turbine"/>
  </joint>
  <link name="chest_l_jet_turbine">
    <inertial>
      <mass value="2.485121044142475"/>
      <origin xyz="-1.2021870482992192e-6 0.006989391668813405 -0.15859756054561458" rpy="0 -0 0"/>
      <inertia ixx="0.00995696120949495" ixy="9.121988679390884e-6" ixz="1.2765757408929822e-5" iyy="0.008873133869822553" iyz="-1.3408250367438063e-5" izz="0.0050950352814347205"/>
    </inertial>
    <visual>
      <origin xyz="0 0 0" rpy="0 -0 0"/>
      <geometry>
        <mesh filename="package://iRonCub-Mk3/iRonCub/meshes/obj/sim_sea_l_jet_turbine.obj" scale="0.001 0.001 0.001"/>
      </geometry>
      <material name="">
        <color rgba="0.5 0.5 0.5 1"/>
      </material>
    </visual>
    <collision>
      <origin xyz="0 0 0" rpy="0 -0 0"/>
      <geometry>
        <mesh filename="package://iRonCub-Mk3/iRonCub/meshes/obj/sim_sea_l_jet_turbine.obj" scale="0.001 0.001 0.001"/>
      </geometry>
      <material name="">
        <color rgba="0.5 0.5 0.5 1"/>
      </material>
    </collision>
  </link>
  <joint name="r_jet_ft_sensor" type="fixed">
    <origin xyz="0.3000540611713717 0.015279475722925928 -0.17982579844272073" rpy="2.879793265790644 -3.494213743063994e-16 1.5707963267948968"/>
    <parent link="chest_jetpack"/>
    <child link="chest_r_jet_turbine"/>
  </joint>
  <link name="chest_r_jet_turbine">
    <inertial>
      <mass value="2.485121044142475"/>
      <origin xyz="-1.202982383791129e-6 -0.007176625110538154 -0.15859756054561458" rpy="0 -0 0"/>
      <inertia ixx="0.009967969905614368" ixy="-1.0264559868435775e-6" ixz="1.2765689314859367e-5" iyy="0.008873133870962072" iyz="1.1248737016987531e-5" izz="0.005106043978693606"/>
    </inertial>
    <visual>
      <origin xyz="0 0 0" rpy="0 -0 0"/>
      <geometry>
        <mesh filename="package://iRonCub-Mk3/iRonCub/meshes/obj/sim_sea_r_jet_turbine.obj" scale="0.001 0.001 0.001"/>
      </geometry>
      <material name="">
        <color rgba="0.5 0.5 0.5 1"/>
      </material>
    </visual>
    <collision>
      <origin xyz="0 0 0" rpy="0 -0 0"/>
      <geometry>
        <mesh filename="package://iRonCub-Mk3/iRonCub/meshes/obj/sim_sea_r_jet_turbine.obj" scale="0.001 0.001 0.001"/>
      </geometry>
      <material name="">
        <color rgba="0.5 0.5 0.5 1"/>
      </material>
    </collision>
  </link>
  <joint name="r_shoulder_roll" type="revolute">
    <origin xyz="0.007489169544993426 -0.1115000000000005 4.029137951449893e-4" rpy="0.17453292519940572 -0.05374771349722806 -3.796894575208941e-14"/>
    <axis xyz="-1.0000000000000002 -1.2906342661267445e-15 -1.3322676295501878e-15"/>
    <parent link="r_shoulder_1"/>
    <child link="r_shoulder_2"/>
    <limit lower="0.20943951023931956" upper="2.8448866807507573" effort="1e+9" velocity="1e+9"/>
    <dynamics damping="2" friction="0"/>
  </joint>
  <link name="r_shoulder_2">
    <inertial>
      <mass value="0.4394303347087956"/>
      <origin xyz="0.00510875359504365 -2.132499365749274e-4 -0.02040339841293008" rpy="0 -0 0"/>
      <inertia ixx="2.9050558660832e-4" ixy="-9.55296844933149e-7" ixz="-9.726975632935912e-5" iyy="4.2748691407969944e-4" iyz="-1.2248714692549955e-6" izz="2.666198611531782e-4"/>
    </inertial>
    <visual>
      <origin xyz="0 0 0" rpy="0 -0 0"/>
      <geometry>
        <mesh filename="package://iRonCub-Mk3/iRonCub/meshes/obj/sim_icub3_r_shoulder_2.obj" scale="0.001 0.001 0.001"/>
      </geometry>
      <material name="">
        <color rgba="0.5 0.5 0.5 1"/>
      </material>
    </visual>
    <collision>
      <origin xyz="0 0 0" rpy="0 -0 0"/>
      <geometry>
        <mesh filename="package://iRonCub-Mk3/iRonCub/meshes/obj/sim_icub3_r_shoulder_2.obj" scale="0.001 0.001 0.001"/>
      </geometry>
      <material name="">
        <color rgba="0.5 0.5 0.5 1"/>
      </material>
    </collision>
  </link>
  <joint name="r_arm_ft_sensor" type="fixed">
    <origin xyz="-0.0068499999999999985 0 -0.05429999999999999" rpy="-7.632783294297952e-17 -2.8449465006019636e-16 1.77635683940025e-15"/>
    <parent link="r_shoulder_2"/>
    <child link="r_shoulder_3"/>
  </joint>
  <link name="r_shoulder_3">
    <inertial>
      <mass value="0.27146627275996604"/>
      <origin xyz="-8.311677995866476e-5 -3.0654831449872244e-5 -0.007966545320293922" rpy="0 -0 0"/>
      <inertia ixx="7.62028421611034e-5" ixy="-3.654997743780583e-7" ixz="-3.624007789431451e-8" iyy="7.648716704363912e-5" iyz="-6.05135565679442e-8" izz="1.274018476627971e-4"/>
    </inertial>
    <visual>
      <origin xyz="0 0 0" rpy="0 -0 0"/>
      <geometry>
        <mesh filename="package://iRonCub-Mk3/iRonCub/meshes/obj/sim_icub3_r_shoulder_3.obj" scale="0.001 0.001 0.001"/>
      </geometry>
      <material name="">
        <color rgba="0.5 0.5 0.5 1"/>
      </material>
    </visual>
    <collision>
      <origin xyz="0 0 0" rpy="0 -0 0"/>
      <geometry>
        <mesh filename="package://iRonCub-Mk3/iRonCub/meshes/obj/sim_icub3_r_shoulder_3.obj" scale="0.001 0.001 0.001"/>
      </geometry>
      <material name="">
        <color rgba="0.5 0.5 0.5 1"/>
      </material>
    </collision>
  </link>
  <joint name="r_shoulder_yaw" type="revolute">
    <origin xyz="-2.0816681711721685e-17 2.220446049250313e-16 -0.022500000000000034" rpy="-1.2712053631958017e-14 -6.501743587961073e-15 8.382183835919908e-15"/>
    <axis xyz="6.349087922075112e-15 -1.2850831510036185e-14 1.000000000000002"/>
    <parent link="r_shoulder_3"/>
    <child link="r_upper_arm"/>
    <limit lower="-0.8726646259971648" upper="1.3962634015954636" effort="1e+9" velocity="1e+9"/>
    <dynamics damping="2" friction="0"/>
  </joint>
  <link name="r_upper_arm">
    <inertial>
      <mass value="1.6772906895585853"/>
      <origin xyz="0.0010477411494388446 -0.0025592471121872735 -0.050652982369893636" rpy="0 -0 0"/>
      <inertia ixx="0.0029869197761717373" ixy="1.9760838161733013e-5" ixz="7.516752031618085e-5" iyy="0.003091158059685315" iyz="-1.155261578180163e-4" izz="0.001285657073633261"/>
    </inertial>
    <visual>
      <origin xyz="0 0 0" rpy="0 -0 0"/>
      <geometry>
        <mesh filename="package://iRonCub-Mk3/iRonCub/meshes/obj/sim_icub3_r_upperarm.obj" scale="0.001 0.001 0.001"/>
      </geometry>
      <material name="">
        <color rgba="0.5 0.5 0.5 1"/>
      </material>
    </visual>
    <collision>
      <origin xyz="0 0 0" rpy="0 -0 0"/>
      <geometry>
        <mesh filename="package://iRonCub-Mk3/iRonCub/meshes/obj/sim_icub3_r_upperarm.obj" scale="0.001 0.001 0.001"/>
      </geometry>
      <material name="">
        <color rgba="0.5 0.5 0.5 1"/>
      </material>
    </collision>
  </link>
  <joint name="r_elbow" type="revolute">
    <origin xyz="0.00999999999999937 0.0015000000000010838 -0.12369999999999985" rpy="-1.3211653993039333e-14 1.214306433183765e-16 -8.104628079763618e-15"/>
    <axis xyz="1.287164819174785e-15 -1.0000000000000024 9.38832345198644e-15"/>
    <parent link="r_upper_arm"/>
    <child link="r_elbow_1"/>
    <limit lower="-0.05235987755982989" upper="1.3089969389957472" effort="1e+9" velocity="1e+9"/>
    <dynamics damping="2" friction="0"/>
  </joint>
  <link name="r_elbow_1">
    <inertial>
      <mass value="0.83"/>
      <origin xyz="-0.013603053872079232 -0.02226045303391494 -0.10863395029513051" rpy="0 -0 0"/>
      <inertia ixx="0.004242358044379757" ixy="-2.4488197119050493e-5" ixz="-1.186805284910655e-4" iyy="0.003540593427407141" iyz="-7.481896083345722e-4" izz="0.002021115608220977"/>
    </inertial>
    <visual>
      <origin xyz="0 0 0" rpy="0 -0 0"/>
      <geometry>
        <mesh filename="package://iRonCub-Mk3/iRonCub/meshes/obj/sim_icub3_r_elbow_prosup.obj" scale="0.001 0.001 0.001"/>
      </geometry>
      <material name="">
        <color rgba="0.5 0.5 0.5 1"/>
      </material>
    </visual>
    <collision>
      <origin xyz="0 0 0" rpy="0 -0 0"/>
      <geometry>
        <mesh filename="package://iRonCub-Mk3/iRonCub/meshes/obj/sim_icub3_r_elbow_prosup.obj" scale="0.001 0.001 0.001"/>
      </geometry>
      <material name="">
        <color rgba="0.5 0.5 0.5 1"/>
      </material>
    </collision>
  </link>
  <joint name="r_elbow_turbine" type="fixed">
    <origin xyz="-0.014925050442282123 -0.09227960464730806 -0.312001522804658" rpy="-3.14159265358979 1.1900203045200897e-14 -1.308996938995748"/>
    <parent link="r_elbow_1"/>
    <child link="r_arm_jet_turbine"/>
  </joint>
  <link name="r_arm_jet_turbine">
    <inertial>
      <mass value="2.1150000034532423"/>
      <origin xyz="4.92446747412667e-5 -6.625496324369484e-5 -0.15870231656106432" rpy="0 -0 0"/>
      <inertia ixx="0.008237099476525477" ixy="4.0675330356338205e-6" ixz="1.269067681845511e-5" iyy="0.00823782510793148" iyz="-1.1204606768599025e-6" izz="0.0027762889100932035"/>
    </inertial>
    <visual>
      <origin xyz="0 0 0" rpy="0 -0 0"/>
      <geometry>
        <mesh filename="package://iRonCub-Mk3/iRonCub/meshes/obj/sim_sea_r_arm_p250.obj" scale="0.001 0.001 0.001"/>
      </geometry>
      <material name="">
        <color rgba="0.5 0.5 0.5 1"/>
      </material>
    </visual>
    <collision>
      <origin xyz="0 0 0" rpy="0 -0 0"/>
      <geometry>
        <mesh filename="package://iRonCub-Mk3/iRonCub/meshes/obj/sim_sea_r_arm_p250.obj" scale="0.001 0.001 0.001"/>
      </geometry>
      <material name="">
        <color rgba="0.5 0.5 0.5 1"/>
      </material>
    </collision>
  </link>
  <joint name="l_shoulder_roll" type="revolute">
    <origin xyz="0.004992779696632584 0.11149999999999995 2.6860919733985925e-4" rpy="-0.17453292519939406 -0.05374771361267909 -3.946991432525758e-15"/>
    <axis xyz="1 2.0043905771260917e-11 -1.136720509387068e-10"/>
    <parent link="l_shoulder_1"/>
    <child link="l_shoulder_2"/>
    <limit lower="0.20943951023931956" upper="2.8448866807507573" effort="1e+9" velocity="1e+9"/>
    <dynamics damping="2" friction="0"/>
  </joint>
  <link name="l_shoulder_2">
    <inertial>
      <mass value="0.4394303347087956"/>
      <origin xyz="0.007668876852690326 1.879124475731575e-4 -0.020403398412930034" rpy="0 -0 0"/>
      <inertia ixx="2.9051005317488134e-4" ixy="1.1577918109131243e-6" ixz="-9.782497267258872e-5" iyy="4.2882800044558223e-4" iyz="1.4446762246615074e-6" izz="2.679654140856268e-4"/>
    </inertial>
    <visual>
      <origin xyz="0 0 0" rpy="0 -0 0"/>
      <geometry>
        <mesh filename="package://iRonCub-Mk3/iRonCub/meshes/obj/sim_icub3_l_shoulder_2.obj" scale="0.001 0.001 0.001"/>
      </geometry>
      <material name="">
        <color rgba="0.5 0.5 0.5 1"/>
      </material>
    </visual>
    <collision>
      <origin xyz="0 0 0" rpy="0 -0 0"/>
      <geometry>
        <mesh filename="package://iRonCub-Mk3/iRonCub/meshes/obj/sim_icub3_l_shoulder_2.obj" scale="0.001 0.001 0.001"/>
      </geometry>
      <material name="">
        <color rgba="0.5 0.5 0.5 1"/>
      </material>
    </collision>
  </link>
  <joint name="l_arm_ft_sensor" type="fixed">
    <origin xyz="-0.00435000000000001 2.7755575615628914e-17 -0.054300000000000063" rpy="2.636779683484746e-16 3.8163916471489756e-17 1.5543122344752186e-15"/>
    <parent link="l_shoulder_2"/>
    <child link="l_shoulder_3"/>
  </joint>
  <link name="l_shoulder_3">
    <inertial>
      <mass value="0.27146627275996604"/>
      <origin xyz="-9.556659554113903e-5 3.065483169495398e-5 -0.00796654532029388" rpy="0 -0 0"/>
      <inertia ixx="7.620284216108841e-5" ixy="3.951881102937488e-7" ixz="-6.239571176080733e-8" iyy="7.64865631465354e-5" iyz="6.051355594562232e-8" izz="1.2740124376568396e-4"/>
    </inertial>
    <visual>
      <origin xyz="0 0 0" rpy="0 -0 0"/>
      <geometry>
        <mesh filename="package://iRonCub-Mk3/iRonCub/meshes/obj/sim_icub3_l_shoulder_3.obj" scale="0.001 0.001 0.001"/>
      </geometry>
      <material name="">
        <color rgba="0.5 0.5 0.5 1"/>
      </material>
    </visual>
    <collision>
      <origin xyz="0 0 0" rpy="0 -0 0"/>
      <geometry>
        <mesh filename="package://iRonCub-Mk3/iRonCub/meshes/obj/sim_icub3_l_shoulder_3.obj" scale="0.001 0.001 0.001"/>
      </geometry>
      <material name="">
        <color rgba="0.5 0.5 0.5 1"/>
      </material>
    </collision>
  </link>
  <joint name="l_shoulder_yaw" type="revolute">
    <origin xyz="-8.730093037367936e-12 1.2878587085651816e-14 -0.022500000000073794" rpy="-3.351485755587198e-15 1.1364280697034879e-10 2.0049795157461903e-11"/>
    <axis xyz="1.136428416648183e-10 3.323730179970867e-15 -0.999999999999998"/>
    <parent link="l_shoulder_3"/>
    <child link="l_upper_arm"/>
    <limit lower="-0.8726646259971648" upper="1.3962634015954636" effort="1e+9" velocity="1e+9"/>
    <dynamics damping="2" friction="0"/>
  </joint>
  <link name="l_upper_arm">
    <inertial>
      <mass value="1.6755955548988626"/>
      <origin xyz="0.0010548346434496522 0.0024662548452177857 -0.050596864463127444" rpy="0 -0 0"/>
      <inertia ixx="0.002989089988120242" ixy="-2.1310259457166117e-5" ixz="7.691929278267632e-5" iyy="0.0030866449653698886" iyz="1.064905905893311e-4" izz="0.0012925055872225403"/>
    </inertial>
    <visual>
      <origin xyz="0 0 0" rpy="0 -0 0"/>
      <geometry>
        <mesh filename="package://iRonCub-Mk3/iRonCub/meshes/obj/sim_icub3_l_upperarm.obj" scale="0.001 0.001 0.001"/>
      </geometry>
      <material name="">
        <color rgba="0.5 0.5 0.5 1"/>
      </material>
    </visual>
    <collision>
      <origin xyz="0 0 0" rpy="0 -0 0"/>
      <geometry>
        <mesh filename="package://iRonCub-Mk3/iRonCub/meshes/obj/sim_icub3_l_upperarm.obj" scale="0.001 0.001 0.001"/>
      </geometry>
      <material name="">
        <color rgba="0.5 0.5 0.5 1"/>
      </material>
    </collision>
  </link>
  <joint name="l_elbow" type="revolute">
    <origin xyz="0.009999999999996283 -0.0014999999999997793 -0.12369999999999949" rpy="-2.9212743335449495e-15 1.0057696342435918e-10 -8.215650382226179e-15"/>
    <axis xyz="2.1285057046745952e-15 -0.9999999999999974 4.024558463653784e-15"/>
    <parent link="l_upper_arm"/>
    <child link="l_elbow_1"/>
    <limit lower="-0.05235987755982989" upper="1.3089969389957472" effort="1e+9" velocity="1e+9"/>
    <dynamics damping="2" friction="0"/>
  </joint>
  <link name="l_elbow_1">
    <inertial>
      <mass value="0.837"/>
      <origin xyz="-0.013599522111457504 0.02224577873432515 -0.10856865298483542" rpy="0 -0 0"/>
      <inertia ixx="0.0042489697155005356" ixy="2.4567899636306935e-5" ixz="-1.1909293276790968e-4" iyy="0.0035468945903827723" iyz="7.496416692517622e-4" izz="0.0020214652393304396"/>
    </inertial>
    <visual>
      <origin xyz="0 0 0" rpy="0 -0 0"/>
      <geometry>
        <mesh filename="package://iRonCub-Mk3/iRonCub/meshes/obj/sim_icub3_l_elbow_prosup.obj" scale="0.001 0.001 0.001"/>
      </geometry>
      <material name="">
        <color rgba="0.5 0.5 0.5 1"/>
      </material>
    </visual>
    <collision>
      <origin xyz="0 0 0" rpy="0 -0 0"/>
      <geometry>
        <mesh filename="package://iRonCub-Mk3/iRonCub/meshes/obj/sim_icub3_l_elbow_prosup.obj" scale="0.001 0.001 0.001"/>
      </geometry>
      <material name="">
        <color rgba="0.5 0.5 0.5 1"/>
      </material>
    </collision>
  </link>
  <joint name="l_elbow_turbine" type="fixed">
    <origin xyz="-0.014999971294355915 0.09171052427705503 -0.31200152280465554" rpy="3.141592653589783 1.3461454173580023e-14 -1.5707963267949192"/>
    <parent link="l_elbow_1"/>
    <child link="l_arm_jet_turbine"/>
  </joint>
  <link name="l_arm_jet_turbine">
    <inertial>
      <mass value="2.1150000034532423"/>
      <origin xyz="4.924467474098915e-5 -6.625496324388913e-5 -0.15870231656106382" rpy="0 -0 0"/>
      <inertia ixx="0.008237099476525386" ixy="4.067533035608667e-6" ixz="1.2690676818385939e-5" iyy="0.00823782510793146" iyz="-1.1204606768582762e-6" izz="0.002776288910093314"/>
    </inertial>
    <visual>
      <origin xyz="0 0 0" rpy="0 -0 0"/>
      <geometry>
        <mesh filename="package://iRonCub-Mk3/iRonCub/meshes/obj/sim_sea_l_arm_p250.obj" scale="0.001 0.001 0.001"/>
      </geometry>
      <material name="">
        <color rgba="0.5 0.5 0.5 1"/>
      </material>
    </visual>
    <collision>
      <origin xyz="0 0 0" rpy="0 -0 0"/>
      <geometry>
        <mesh filename="package://iRonCub-Mk3/iRonCub/meshes/obj/sim_sea_l_arm_p250.obj" scale="0.001 0.001 0.001"/>
      </geometry>
      <material name="">
        <color rgba="0.5 0.5 0.5 1"/>
      </material>
    </collision>
  </link>
  <joint name="r_hip_roll" type="revolute">
    <origin xyz="-0.04729999999999998 -0.03309999999999986 -0.009000000000000064" rpy="7.216449660063586e-16 2.686997451646527e-31 -2.7468378994038928e-15"/>
    <axis xyz="-1 1.2968929435325477e-16 2.1190202345730036e-15"/>
    <parent link="r_hip_1"/>
    <child link="r_hip_2"/>
    <limit lower="-0.17453292519943295" upper="1.9547687622336491" effort="1e+9" velocity="1e+9"/>
    <dynamics damping="2" friction="0"/>
  </joint>
  <link name="r_hip_2">
    <inertial>
      <mass value="1.833614649998661"/>
      <origin xyz="-0.003963452708457164 -7.011349050914384e-5 -0.03753475266778922" rpy="0 -0 0"/>
      <inertia ixx="0.0030671505582571274" ixy="-4.786192991358219e-6" ixz="9.790337810980146e-4" iyy="0.005407658251894156" iyz="3.3750052721298247e-6" izz="0.003388232477858492"/>
    </inertial>
    <visual>
      <origin xyz="0 0 0" rpy="0 -0 0"/>
      <geometry>
        <mesh filename="package://iRonCub-Mk3/iRonCub/meshes/obj/sim_icub3_r_hip_2.obj" scale="0.001 0.001 0.001"/>
      </geometry>
      <material name="">
        <color rgba="0.5 0.5 0.5 1"/>
      </material>
    </visual>
    <collision>
      <origin xyz="0 0 0" rpy="0 -0 0"/>
      <geometry>
        <mesh filename="package://iRonCub-Mk3/iRonCub/meshes/obj/sim_icub3_r_hip_2.obj" scale="0.001 0.001 0.001"/>
      </geometry>
      <material name="">
        <color rgba="0.5 0.5 0.5 1"/>
      </material>
    </collision>
  </link>
  <joint name="r_leg_ft_sensor" type="fixed">
    <origin xyz="0.036700000000000066 -4.163336342344337e-17 -0.08969999999999972" rpy="-6.089063069260033e-15 1.644234531352233e-30 -5.5511151231252706e-17"/>
    <parent link="r_hip_2"/>
    <child link="r_hip_3"/>
  </joint>
  <link name="r_hip_3">
    <inertial>
      <mass value="2.287"/>
      <origin xyz="0.0024329299939115923 0.012333660595895753 -0.03824169008061662" rpy="0 -0 0"/>
      <inertia ixx="0.0038578854356886246" ixy="2.141404125628434e-6" ixz="1.0787230765312922e-5" iyy="0.004113718549864092" iyz="-1.3207662734870832e-4" izz="0.003825213884905135"/>
    </inertial>
    <visual>
      <origin xyz="0 0 0" rpy="0 -0 0"/>
      <geometry>
        <mesh filename="package://iRonCub-Mk3/iRonCub/meshes/obj/sim_icub3_r_hip_3.obj" scale="0.001 0.001 0.001"/>
      </geometry>
      <material name="">
        <color rgba="0.5 0.5 0.5 1"/>
      </material>
    </visual>
    <collision>
      <origin xyz="0 0 0" rpy="0 -0 0"/>
      <geometry>
        <mesh filename="package://iRonCub-Mk3/iRonCub/meshes/obj/sim_icub3_r_hip_3.obj" scale="0.001 0.001 0.001"/>
      </geometry>
      <material name="">
        <color rgba="0.5 0.5 0.5 1"/>
      </material>
    </collision>
  </link>
  <joint name="r_hip_yaw" type="revolute">
    <origin xyz="-8.673617379884035e-17 0.014999999999999993 -0.07089999999999885" rpy="8.466863913638833e-18 1.1277593951375457e-15 -2.2204460492503136e-16"/>
    <axis xyz="-6.449821556600818e-19 -9.607200978997899e-18 -0.9999999999999998"/>
    <parent link="r_hip_3"/>
    <child link="r_upper_leg"/>
    <limit lower="-1.3962634015954636" upper="1.3962634015954636" effort="1e+9" velocity="1e+9"/>
    <dynamics damping="2" friction="0"/>
  </joint>
  <link name="r_upper_leg">
    <inertial>
      <mass value="0.9402980287060128"/>
      <origin xyz="0.005240343603986914 -0.001499805397626633 -0.05185726677356867" rpy="0 -0 0"/>
      <inertia ixx="0.002407761239518152" ixy="2.5566474473690137e-5" ixz="2.275376339918301e-4" iyy="0.0019244659655677687" iyz="-1.0254206344598647e-4" izz="0.0010461394458734497"/>
    </inertial>
    <visual>
      <origin xyz="0 0 0" rpy="0 -0 0"/>
      <geometry>
        <mesh filename="package://iRonCub-Mk3/iRonCub/meshes/obj/sim_icub3_r_upper_leg.obj" scale="0.001 0.001 0.001"/>
      </geometry>
      <material name="">
        <color rgba="0.5 0.5 0.5 1"/>
      </material>
    </visual>
    <collision>
      <origin xyz="0 0 0" rpy="0 -0 0"/>
      <geometry>
        <mesh filename="package://iRonCub-Mk3/iRonCub/meshes/obj/sim_icub3_r_upper_leg.obj" scale="0.001 0.001 0.001"/>
      </geometry>
      <material name="">
        <color rgba="0.5 0.5 0.5 1"/>
      </material>
    </collision>
  </link>
  <joint name="r_knee" type="revolute">
    <origin xyz="0.015000000000000142 -0.024899999999999874 -0.10620000000000207" rpy="1.8143800820083272e-29 -1.127759395137545e-15 5.981115056656332e-15"/>
    <axis xyz="-1.084380013033695e-16 -1 8.486788880534846e-17"/>
    <parent link="r_upper_leg"/>
    <child link="r_lower_leg"/>
    <limit lower="-1.2217304763960306" upper="0.08726646259971647" effort="1e+9" velocity="1e+9"/>
    <dynamics damping="2" friction="0"/>
  </joint>
  <link name="r_lower_leg">
    <inertial>
      <mass value="5.249438043974956"/>
      <origin xyz="-0.013102437510550726 0.02198674723566333 -0.12726139820258864" rpy="0 -0 0"/>
      <inertia ixx="0.055234399867894676" ixy="1.0912006804812842e-4" ixz="-1.3145760496561729e-4" iyy="0.05774844579077887" iyz="2.6101734067283597e-4" izz="0.005983140588196573"/>
    </inertial>
    <visual>
      <origin xyz="0 0 0" rpy="0 -0 0"/>
      <geometry>
        <mesh filename="package://iRonCub-Mk3/iRonCub/meshes/obj/sim_icub3_r_lower_leg.obj" scale="0.001 0.001 0.001"/>
      </geometry>
      <material name="">
        <color rgba="0.5 0.5 0.5 1"/>
      </material>
    </visual>
    <collision>
      <origin xyz="0 0 0" rpy="0 -0 0"/>
      <geometry>
        <mesh filename="package://iRonCub-Mk3/iRonCub/meshes/obj/sim_icub3_r_lower_leg.obj" scale="0.001 0.001 0.001"/>
      </geometry>
      <material name="">
        <color rgba="0.5 0.5 0.5 1"/>
      </material>
    </collision>
  </link>
  <joint name="r_ankle_pitch" type="revolute">
    <origin xyz="-3.365363543395006e-16 4.999999999998617e-4 -0.2559881157599204" rpy="1.0547118733938821e-15 -8.493638465627041e-30 4.4280926965196554e-16"/>
    <axis xyz="1.3179285671219242e-17 1 -1.4993762623373327e-15"/>
    <parent link="r_lower_leg"/>
    <child link="r_ankle_1"/>
    <limit lower="-0.7853981633974483" upper="0.7853981633974483" effort="1e+9" velocity="1e+9"/>
    <dynamics damping="2" friction="0"/>
  </joint>
  <link name="r_ankle_1">
    <inertial>
      <mass value="0.37817767154054266"/>
      <origin xyz="-0.005665751779017677 4.763569575093607e-4 -0.015186733232055771" rpy="0 -0 0"/>
      <inertia ixx="3.1751215066080354e-4" ixy="3.75663080896285e-5" ixz="-2.7019300315981074e-5" iyy="7.248143014619804e-4" iyz="6.278682324925938e-5" izz="5.682941969820695e-4"/>
    </inertial>
    <visual>
      <origin xyz="0 0 0" rpy="0 -0 0"/>
      <geometry>
        <mesh filename="package://iRonCub-Mk3/iRonCub/meshes/obj/sim_icub3_r_ankle_1.obj" scale="0.001 0.001 0.001"/>
      </geometry>
      <material name="">
        <color rgba="0.5 0.5 0.5 1"/>
      </material>
    </visual>
    <collision>
      <origin xyz="0 0 0" rpy="0 -0 0"/>
      <geometry>
        <mesh filename="package://iRonCub-Mk3/iRonCub/meshes/obj/sim_icub3_r_ankle_1.obj" scale="0.001 0.001 0.001"/>
      </geometry>
      <material name="">
        <color rgba="0.5 0.5 0.5 1"/>
      </material>
    </collision>
  </link>
  <joint name="r_ankle_roll" type="revolute">
    <origin xyz="-0.052750000000000005 0.018200000000000077 -0.035000000000001585" rpy="6.230888022028647e-17 -3.720370649524174e-14 -7.888609052210118e-31"/>
    <axis xyz="-1 1.1174132972227575e-16 2.261321834258238e-15"/>
    <parent link="r_ankle_1"/>
    <child link="r_ankle_2"/>
    <limit lower="-0.4363323129985824" upper="0.4363323129985824" effort="1e+9" velocity="1e+9"/>
    <dynamics damping="2" friction="0"/>
  </joint>
  <link name="r_ankle_2">
    <inertial>
      <mass value="1.4240816841588382"/>
      <origin xyz="0.041737128896344386 5.619171243621823e-5 -0.02559370721320453" rpy="0 -0 0"/>
      <inertia ixx="0.001650700345398901" ixy="6.178758417180746e-6" ixz="0.0011521919955968642" iyy="0.007756874276920412" iyz="-1.5066372506149793e-6" izz="0.007486003373910294"/>
    </inertial>
    <visual>
      <origin xyz="0 0 0" rpy="0 -0 0"/>
      <geometry>
        <mesh filename="package://iRonCub-Mk3/iRonCub/meshes/obj/sim_icub3_r_ankle_2.obj" scale="0.001 0.001 0.001"/>
      </geometry>
      <material name="">
        <color rgba="0.5 0.5 0.5 1"/>
      </material>
    </visual>
    <collision>
      <origin xyz="0 0 0" rpy="0 -0 0"/>
      <geometry>
        <mesh filename="package://iRonCub-Mk3/iRonCub/meshes/obj/sim_icub3_r_ankle_2.obj" scale="0.001 0.001 0.001"/>
      </geometry>
      <material name="">
        <color rgba="0.5 0.5 0.5 1"/>
      </material>
    </collision>
  </link>
  <joint name="r_foot_front_ft_sensor" type="fixed">
    <origin xyz="0.13524999999999748 1.3877787807814457e-17 -0.06579999999999997" rpy="7.888609052210116e-31 3.836494265472103e-14 5.67910914292208e-17"/>
    <parent link="r_ankle_2"/>
    <child link="r_foot_front"/>
  </joint>
  <link name="r_foot_front">
    <inertial>
      <mass value="0.1857731666576178"/>
      <origin xyz="-4.181506435531057e-4 4.850217574709492e-4 0.005581042936262604" rpy="0 -0 0"/>
      <inertia ixx="3.88974837777633e-4" ixy="1.2018769888963683e-5" ixz="7.297273810247112e-5" iyy="4.628429799819053e-4" iyz="-3.069990924531882e-5" izz="4.138601909394049e-4"/>
    </inertial>
    <visual>
      <origin xyz="0 0 0" rpy="0 -0 0"/>
      <geometry>
        <mesh filename="package://iRonCub-Mk3/iRonCub/meshes/obj/sim_icub3_r_foot_front.obj" scale="0.001 0.001 0.001"/>
      </geometry>
      <material name="">
        <color rgba="0.5 0.5 0.5 1"/>
      </material>
    </visual>
    <collision>
      <origin xyz="0 0 0" rpy="0 -0 0"/>
      <geometry>
        <mesh filename="package://iRonCub-Mk3/iRonCub/meshes/obj/sim_icub3_r_foot_front.obj" scale="0.001 0.001 0.001"/>
      </geometry>
      <material name="">
        <color rgba="0.5 0.5 0.5 1"/>
      </material>
    </collision>
  </link>
  <joint name="r_foot_rear_ft_sensor" type="fixed">
    <origin xyz="0.01599999999999748 1.3877787807814457e-17 -0.06579999999999997" rpy="3.944304526105058e-30 3.836494265472102e-14 5.679109142921843e-17"/>
    <parent link="r_ankle_2"/>
    <child link="r_foot_rear"/>
  </joint>
  <link name="r_foot_rear">
    <inertial>
      <mass value="0.18484137199451806"/>
      <origin xyz="6.18140812367227e-4 7.08241004708926e-5 0.00351328086527336" rpy="0 -0 0"/>
      <inertia ixx="1.885197871391696e-4" ixy="-1.6517766365448337e-7" ixz="-1.333838459275122e-6" iyy="2.4650691609085087e-4" iyz="-2.9493102919083806e-6" izz="3.76966628938421e-4"/>
    </inertial>
    <visual>
      <origin xyz="0 0 0" rpy="0 -0 0"/>
      <geometry>
        <mesh filename="package://iRonCub-Mk3/iRonCub/meshes/obj/sim_icub3_r_foot_rear.obj" scale="0.001 0.001 0.001"/>
      </geometry>
      <material name="">
        <color rgba="0.5 0.5 0.5 1"/>
      </material>
    </visual>
    <collision>
      <origin xyz="0 0 0" rpy="0 -0 0"/>
      <geometry>
        <mesh filename="package://iRonCub-Mk3/iRonCub/meshes/obj/sim_icub3_r_foot_rear.obj" scale="0.001 0.001 0.001"/>
      </geometry>
      <material name="">
        <color rgba="0.5 0.5 0.5 1"/>
      </material>
    </collision>
  </link>
  <joint name="l_hip_roll" type="revolute">
    <origin xyz="-0.0472500000000006 0.03310000000000002 -0.009000000000000008" rpy="1.9428902930940228e-15 3.59183578855383e-18 1.1102230246251519e-16"/>
    <axis xyz="1 -1.7225464241988584e-16 -2.1891268435602713e-16"/>
    <parent link="l_hip_1"/>
    <child link="l_hip_2"/>
    <limit lower="-0.17453292519943295" upper="1.9547687622336491" effort="1e+9" velocity="1e+9"/>
    <dynamics damping="2" friction="0"/>
  </joint>
  <link name="l_hip_2">
    <inertial>
      <mass value="1.8336146355226512"/>
      <origin xyz="-0.003963823462979028 5.4915974113028954e-5 -0.03753786360473582" rpy="0 -0 0"/>
      <inertia ixx="0.003066965059357712" ixy="4.222906828090903e-6" ixz="9.784726858463354e-4" iyy="0.005406838837606385" iyz="-3.2731216652879554e-6" izz="0.0033884858746293946"/>
    </inertial>
    <visual>
      <origin xyz="0 0 0" rpy="0 -0 0"/>
      <geometry>
        <mesh filename="package://iRonCub-Mk3/iRonCub/meshes/obj/sim_icub3_l_hip_2.obj" scale="0.001 0.001 0.001"/>
      </geometry>
      <material name="">
        <color rgba="0.5 0.5 0.5 1"/>
      </material>
    </visual>
    <collision>
      <origin xyz="0 0 0" rpy="0 -0 0"/>
      <geometry>
        <mesh filename="package://iRonCub-Mk3/iRonCub/meshes/obj/sim_icub3_l_hip_2.obj" scale="0.001 0.001 0.001"/>
      </geometry>
      <material name="">
        <color rgba="0.5 0.5 0.5 1"/>
      </material>
    </collision>
  </link>
  <joint name="l_leg_ft_sensor" type="fixed">
    <origin xyz="0.036699999999999955 2.7755575615628914e-17 -0.08970000000000022" rpy="-1.281858686408453e-16 -3.5918357885545286e-18 -1.3404913655338114e-17"/>
    <parent link="l_hip_2"/>
    <child link="l_hip_3"/>
  </joint>
  <link name="l_hip_3">
    <inertial>
      <mass value="2.287"/>
      <origin xyz="0.002441657177412888 -0.012306897913026221 -0.038198708758093114" rpy="0 -0 0"/>
      <inertia ixx="0.0038139398541961536" ixy="-3.0418371566406135e-6" ixz="9.618718639831076e-6" iyy="0.004070330408064402" iyz="1.3751070132040277e-4" izz="0.003820323869788303"/>
    </inertial>
    <visual>
      <origin xyz="0 0 0" rpy="0 -0 0"/>
      <geometry>
        <mesh filename="package://iRonCub-Mk3/iRonCub/meshes/obj/sim_icub3_l_hip_3.obj" scale="0.001 0.001 0.001"/>
      </geometry>
      <material name="">
        <color rgba="0.5 0.5 0.5 1"/>
      </material>
    </visual>
    <collision>
      <origin xyz="0 0 0" rpy="0 -0 0"/>
      <geometry>
        <mesh filename="package://iRonCub-Mk3/iRonCub/meshes/obj/sim_icub3_l_hip_3.obj" scale="0.001 0.001 0.001"/>
      </geometry>
      <material name="">
        <color rgba="0.5 0.5 0.5 1"/>
      </material>
    </collision>
  </link>
  <joint name="l_hip_yaw" type="revolute">
    <origin xyz="2.42861286636753e-17 -0.014999999999999875 -0.07089999999999985" rpy="2.1856686386546657e-15 9.123888478787322e-16 1.6653345369376246e-16"/>
    <axis xyz="1.108768777118629e-18 -1.1127924608260968e-17 1"/>
    <parent link="l_hip_3"/>
    <child link="l_upper_leg"/>
    <limit lower="-1.3962634015954636" upper="1.3962634015954636" effort="1e+9" velocity="1e+9"/>
    <dynamics damping="2" friction="0"/>
  </joint>
  <link name="l_upper_leg">
    <inertial>
      <mass value="0.9402980337939509"/>
      <origin xyz="0.005238111641087078 0.0014993100955970201 -0.05185129954426432" rpy="0 -0 0"/>
      <inertia ixx="0.0024047142437120463" ixy="-2.561537238621913e-5" ixz="2.2710797569398762e-4" iyy="0.0019214681467854904" iyz="1.0259690197735792e-4" izz="0.0010462331837568272"/>
    </inertial>
    <visual>
      <origin xyz="0 0 0" rpy="0 -0 0"/>
      <geometry>
        <mesh filename="package://iRonCub-Mk3/iRonCub/meshes/obj/sim_icub3_l_upper_leg.obj" scale="0.001 0.001 0.001"/>
      </geometry>
      <material name="">
        <color rgba="0.5 0.5 0.5 1"/>
      </material>
    </visual>
    <collision>
      <origin xyz="0 0 0" rpy="0 -0 0"/>
      <geometry>
        <mesh filename="package://iRonCub-Mk3/iRonCub/meshes/obj/sim_icub3_l_upper_leg.obj" scale="0.001 0.001 0.001"/>
      </geometry>
      <material name="">
        <color rgba="0.5 0.5 0.5 1"/>
      </material>
    </collision>
  </link>
  <joint name="l_knee" type="revolute">
    <origin xyz="0.014999999999999918 0.02489999999999995 -0.1061999999999999" rpy="-7.888609052210118e-31 -9.195258311043086e-16 3.67642019783261e-15"/>
    <axis xyz="7.741033639899439e-17 -1 -5.247028505138709e-16"/>
    <parent link="l_upper_leg"/>
    <child link="l_lower_leg"/>
    <limit lower="-1.2217304763960306" upper="0.08726646259971647" effort="1e+9" velocity="1e+9"/>
    <dynamics damping="2" friction="0"/>
  </joint>
  <link name="l_lower_leg">
    <inertial>
      <mass value="5.22091999406075"/>
      <origin xyz="-0.01322112433681963 -0.022063173517859455 -0.12639501280377896" rpy="0 -0 0"/>
      <inertia ixx="0.054626484296535716" ixy="-1.0418683353063366e-4" ixz="-1.8594698948841935e-4" iyy="0.05711821743066091" iyz="-3.155420333838515e-4" izz="0.005952976587068344"/>
    </inertial>
    <visual>
      <origin xyz="0 0 0" rpy="0 -0 0"/>
      <geometry>
        <mesh filename="package://iRonCub-Mk3/iRonCub/meshes/obj/sim_icub3_l_lower_leg.obj" scale="0.001 0.001 0.001"/>
      </geometry>
      <material name="">
        <color rgba="0.5 0.5 0.5 1"/>
      </material>
    </visual>
    <collision>
      <origin xyz="0 0 0" rpy="0 -0 0"/>
      <geometry>
        <mesh filename="package://iRonCub-Mk3/iRonCub/meshes/obj/sim_icub3_l_lower_leg.obj" scale="0.001 0.001 0.001"/>
      </geometry>
      <material name="">
        <color rgba="0.5 0.5 0.5 1"/>
      </material>
    </collision>
  </link>
  <joint name="l_ankle_pitch" type="revolute">
    <origin xyz="-2.5673907444456745e-16 -5.00000000000056e-4 -0.25598811575992053" rpy="0 8.753761442151805e-31 4.4408920985006104e-16"/>
    <axis xyz="5.3664452411374737e-17 1 5.24702850513869e-16"/>
    <parent link="l_lower_leg"/>
    <child link="l_ankle_1"/>
    <limit lower="-0.7853981633974483" upper="0.7853981633974483" effort="1e+9" velocity="1e+9"/>
    <dynamics damping="2" friction="0"/>
  </joint>
  <link name="l_ankle_1">
    <inertial>
      <mass value="0.37817767154054266"/>
      <origin xyz="-0.005670912772176413 -4.7758897724493876e-4 -0.015197894505090794" rpy="0 -0 0"/>
      <inertia ixx="3.081887750893901e-4" ixy="-3.766601046399204e-5" ixz="-2.7719614386349423e-5" iyy="7.15535388293082e-4" iyz="-6.236643675910885e-5" izz="5.684249911699869e-4"/>
    </inertial>
    <visual>
      <origin xyz="0 0 0" rpy="0 -0 0"/>
      <geometry>
        <mesh filename="package://iRonCub-Mk3/iRonCub/meshes/obj/sim_icub3_l_ankle_1.obj" scale="0.001 0.001 0.001"/>
      </geometry>
      <material name="">
        <color rgba="0.5 0.5 0.5 1"/>
      </material>
    </visual>
    <collision>
      <origin xyz="0 0 0" rpy="0 -0 0"/>
      <geometry>
        <mesh filename="package://iRonCub-Mk3/iRonCub/meshes/obj/sim_icub3_l_ankle_1.obj" scale="0.001 0.001 0.001"/>
      </geometry>
      <material name="">
        <color rgba="0.5 0.5 0.5 1"/>
      </material>
    </collision>
  </link>
  <joint name="l_ankle_roll" type="revolute">
    <origin xyz="-0.052749999999999964 -0.01819999999999994 -0.03499999999999959" rpy="1.332267629550187e-15 -2.7396392036772293e-16 -1.2767564783189296e-15"/>
    <axis xyz="1 2.589049814262538e-16 -6.02952504474411e-16"/>
    <parent link="l_ankle_1"/>
    <child link="l_ankle_2"/>
    <limit lower="-0.4363323129985824" upper="0.4363323129985824" effort="1e+9" velocity="1e+9"/>
    <dynamics damping="2" friction="0"/>
  </joint>
  <link name="l_ankle_2">
    <inertial>
      <mass value="1.4240392417689562"/>
      <origin xyz="0.04170482219514868 -5.498196070995165e-5 -0.02565166298731636" rpy="0 -0 0"/>
      <inertia ixx="0.0015779041655945864" ixy="-5.369208221472992e-6" ixz="0.0011441485405982454" iyy="0.0076800900450604195" iyz="3.797170877539372e-6" izz="0.0074819442734393865"/>
    </inertial>
    <visual>
      <origin xyz="0 0 0" rpy="0 -0 0"/>
      <geometry>
        <mesh filename="package://iRonCub-Mk3/iRonCub/meshes/obj/sim_icub3_l_ankle_2.obj" scale="0.001 0.001 0.001"/>
      </geometry>
      <material name="">
        <color rgba="0.5 0.5 0.5 1"/>
      </material>
    </visual>
    <collision>
      <origin xyz="0 0 0" rpy="0 -0 0"/>
      <geometry>
        <mesh filename="package://iRonCub-Mk3/iRonCub/meshes/obj/sim_icub3_l_ankle_2.obj" scale="0.001 0.001 0.001"/>
      </geometry>
      <material name="">
        <color rgba="0.5 0.5 0.5 1"/>
      </material>
    </collision>
  </link>
  <joint name="l_foot_front_ft_sensor" type="fixed">
    <origin xyz="0.13525 1.3877787807814457e-17 -0.0658000000000003" rpy="0 -8.326672684689862e-17 -1.9721522630525295e-29"/>
    <parent link="l_ankle_2"/>
    <child link="l_foot_front"/>
  </joint>
  <link name="l_foot_front">
    <inertial>
      <mass value="0.18507432066029245"/>
      <origin xyz="7.678828839985385e-5 -3.9884343929971755e-5 0.004256107071335946" rpy="0 -0 0"/>
      <inertia ixx="2.64746852169386e-4" ixy="-3.667872409244253e-7" ixz="3.615492482485168e-5" iyy="3.3596618166781717e-4" iyz="-2.8071388357581907e-7" izz="3.9058176643447506e-4"/>
    </inertial>
    <visual>
      <origin xyz="0 0 0" rpy="0 -0 0"/>
      <geometry>
        <mesh filename="package://iRonCub-Mk3/iRonCub/meshes/obj/sim_icub3_l_foot_front.obj" scale="0.001 0.001 0.001"/>
      </geometry>
      <material name="">
        <color rgba="0.5 0.5 0.5 1"/>
      </material>
    </visual>
    <collision>
      <origin xyz="0 0 0" rpy="0 -0 0"/>
      <geometry>
        <mesh filename="package://iRonCub-Mk3/iRonCub/meshes/obj/sim_icub3_l_foot_front.obj" scale="0.001 0.001 0.001"/>
      </geometry>
      <material name="">
        <color rgba="0.5 0.5 0.5 1"/>
      </material>
    </collision>
  </link>
  <joint name="l_foot_rear_ft_sensor" type="fixed">
    <origin xyz="0.016 2.7755575615628914e-17 -0.0658000000000003" rpy="0 -8.326672684689941e-17 -1.6171648557030742e-29"/>
    <parent link="l_ankle_2"/>
    <child link="l_foot_rear"/>
  </joint>
  <link name="l_foot_rear">
    <inertial>
      <mass value="0.18460842332874144"/>
      <origin xyz="5.055764240281327e-4 3.345497135118225e-5 0.003658777729100171" rpy="0 -0 0"/>
      <inertia ixx="2.344984943574305e-4" ixy="3.944312886226083e-7" ixz="8.419705694778721e-6" iyy="2.9356694610849796e-4" iyz="-3.493322739080658e-6" izz="3.7763921292923575e-4"/>
    </inertial>
    <visual>
      <origin xyz="0 0 0" rpy="0 -0 0"/>
      <geometry>
        <mesh filename="package://iRonCub-Mk3/iRonCub/meshes/obj/sim_icub3_l_foot_rear.obj" scale="0.001 0.001 0.001"/>
      </geometry>
      <material name="">
        <color rgba="0.5 0.5 0.5 1"/>
      </material>
    </visual>
    <collision>
      <origin xyz="0 0 0" rpy="0 -0 0"/>
      <geometry>
        <mesh filename="package://iRonCub-Mk3/iRonCub/meshes/obj/sim_icub3_l_foot_rear.obj" scale="0.001 0.001 0.001"/>
      </geometry>
      <material name="">
        <color rgba="0.5 0.5 0.5 1"/>
      </material>
    </collision>
  </link>
  <link name="l_arm_ft"/>
  <joint name="l_arm_ft_fixed_joint" type="fixed">
    <origin xyz="-0.004349999999999996 -2.7755575615628914e-17 -0.0543" rpy="3.141592653589793 2.220446049250313e-16 -1.5707963267948952"/>
    <parent link="l_shoulder_2"/>
    <child link="l_arm_ft"/>
  </joint>
  <link name="l_foot_front_ft"/>
  <joint name="l_foot_front_ft_fixed_joint" type="fixed">
    <origin xyz="0.13525 2.7755575615628914e-17 -0.043500000000000094" rpy="-2.368809241389469e-16 -2.3422967732622925e-16 -2.0943951023931957"/>
    <parent link="l_ankle_2"/>
    <child link="l_foot_front_ft"/>
  </joint>
  <link name="l_foot_rear_ft"/>
  <joint name="l_foot_rear_ft_fixed_joint" type="fixed">
    <origin xyz="0.016000000000000007 1.3877787807814457e-17 -0.043500000000000094" rpy="3.1823058817363016e-16 9.88372300613185e-17 -2.0943951023931957"/>
    <parent link="l_ankle_2"/>
    <child link="l_foot_rear_ft"/>
  </joint>
  <link name="l_jet_ft"/>
  <joint name="l_jet_ft_fixed_joint" type="fixed">
    <origin xyz="-0.16427974360580236 0.014990000000000003 -0.03919051679480075" rpy="-3.1415926535897913 -0.26179938779914924 3.141592653589786"/>
    <parent link="chest_jetpack"/>
    <child link="l_jet_ft"/>
  </joint>
  <link name="r_arm_ft"/>
  <joint name="r_arm_ft_fixed_joint" type="fixed">
    <origin xyz="-0.006850000000000002 0 -0.05429999999999999" rpy="3.141592653589793 1.942890293094024e-16 1.5707963267948981"/>
    <parent link="r_shoulder_2"/>
    <child link="r_arm_ft"/>
  </joint>
  <link name="r_foot_front_ft"/>
  <joint name="r_foot_front_ft_fixed_joint" type="fixed">
    <origin xyz="0.13524999999999834 -1.3877787807814457e-17 -0.04349999999999987" rpy="-2.6463649975457505e-16 -1.8615561016663726e-16 -2.0943951023931966"/>
    <parent link="r_ankle_2"/>
    <child link="r_foot_front_ft"/>
  </joint>
  <link name="r_foot_rear_ft"/>
  <joint name="r_foot_rear_ft_fixed_joint" type="fixed">
    <origin xyz="0.015999999999998335 1.3877787807814457e-17 -0.04349999999999998" rpy="2.904750125580036e-16 1.4691129722091128e-16 -2.0943951023931966"/>
    <parent link="r_ankle_2"/>
    <child link="r_foot_rear_ft"/>
  </joint>
  <link name="r_jet_ft"/>
  <joint name="r_jet_ft_fixed_joint" type="fixed">
    <origin xyz="0.16401974360580238 0.014990000000000142 -0.03919051679480075" rpy="-3.141592653589792 -0.2617993877991493 -5.057304790283951e-15"/>
    <parent link="chest_jetpack"/>
    <child link="r_jet_ft"/>
  </joint>
  <link name="l_sole"/>
  <joint name="l_sole_fixed_joint" type="fixed">
    <origin xyz="0.05963000000000001 -1.3877787807814457e-17 1.1102230246251565e-16" rpy="-7.888609052210118e-31 6.024039948780824e-30 -7.888609052210118e-31"/>
    <parent link="l_foot_rear"/>
    <child link="l_sole"/>
  </joint>
  <link name="l_sole_1"/>
  <joint name="l_sole_1_fixed_joint" type="fixed">
    <origin xyz="0.025000000000000036 0.025249999999999995 -1.1102230246251565e-16" rpy="-7.888609052210118e-31 6.024039948780824e-30 -7.888609052210118e-31"/>
    <parent link="l_foot_front"/>
    <child link="l_sole_1"/>
  </joint>
  <link name="l_sole_2"/>
  <joint name="l_sole_2_fixed_joint" type="fixed">
    <origin xyz="0.025000000000000036 -0.02475 0" rpy="-7.888609052210118e-31 6.024039948780824e-30 -7.888609052210118e-31"/>
    <parent link="l_foot_front"/>
    <child link="l_sole_2"/>
  </joint>
  <link name="l_sole_3"/>
  <joint name="l_sole_3_fixed_joint" type="fixed">
    <origin xyz="-0.035 -0.024749999999999987 1.1102230246251565e-16" rpy="-7.888609052210118e-31 6.024039948780824e-30 -7.888609052210118e-31"/>
    <parent link="l_foot_rear"/>
    <child link="l_sole_3"/>
  </joint>
  <link name="l_sole_4"/>
  <joint name="l_sole_4_fixed_joint" type="fixed">
    <origin xyz="-0.034999999999999996 0.030250000000000013 1.1102230246251565e-16" rpy="-7.888609052210118e-31 6.024039948780824e-30 -7.888609052210118e-31"/>
    <parent link="l_foot_rear"/>
    <child link="l_sole_4"/>
  </joint>
  <link name="r_sole"/>
  <joint name="r_sole_fixed_joint" type="fixed">
    <origin xyz="0.05963 0 -1.1102230246251565e-16" rpy="0 -5.227867320768577e-31 -7.888609052210118e-31"/>
    <parent link="r_foot_rear"/>
    <child link="r_sole"/>
  </joint>
  <link name="r_sole_1"/>
  <joint name="r_sole_1_fixed_joint" type="fixed">
    <origin xyz="0.02500000000000001 -0.025149999999999992 1.1102230246251565e-16" rpy="0 -5.227867320768577e-31 -7.888609052210118e-31"/>
    <parent link="r_foot_front"/>
    <child link="r_sole_1"/>
  </joint>
  <link name="r_sole_2"/>
  <joint name="r_sole_2_fixed_joint" type="fixed">
    <origin xyz="0.02499999999999998 0.024850000000000004 1.1102230246251565e-16" rpy="0 -5.227867320768577e-31 -7.888609052210118e-31"/>
    <parent link="r_foot_front"/>
    <child link="r_sole_2"/>
  </joint>
  <link name="r_sole_3"/>
  <joint name="r_sole_3_fixed_joint" type="fixed">
    <origin xyz="-0.034999999999999996 0.024850000000000004 0" rpy="0 -5.227867320768577e-31 -7.888609052210118e-31"/>
    <parent link="r_foot_rear"/>
    <child link="r_sole_3"/>
  </joint>
  <link name="r_sole_4"/>
  <joint name="r_sole_4_fixed_joint" type="fixed">
    <origin xyz="-0.035 -0.03014999999999997 -1.1102230246251565e-16" rpy="0 -5.227867320768577e-31 -7.888609052210118e-31"/>
    <parent link="r_foot_rear"/>
    <child link="r_sole_4"/>
  </joint>
  <link name="base_link"/>
  <joint name="base_link_fixed_joint" type="fixed">
    <origin xyz="0 0 0" rpy="0 -0 0"/>
    <axis xyz="0 0 0"/>
    <parent link="root_link"/>
    <child link="base_link"/>
  </joint>
  <gazebo reference="r_arm_ft_sensor">
    <preserveFixedJoint>true</preserveFixedJoint>
    <!-- For compatibility with SDFormat < 4.4 -->
    <disableFixedJointLumping>true</disableFixedJointLumping>
  </gazebo>
  <gazebo reference="r_jet_ft_sensor">
    <preserveFixedJoint>true</preserveFixedJoint>
    <!-- For compatibility with SDFormat < 4.4 -->
    <disableFixedJointLumping>true</disableFixedJointLumping>
  </gazebo>
  <gazebo reference="l_jet_ft_sensor">
    <preserveFixedJoint>true</preserveFixedJoint>
    <!-- For compatibility with SDFormat < 4.4 -->
    <disableFixedJointLumping>true</disableFixedJointLumping>
  </gazebo>
  <gazebo reference="l_arm_ft_sensor">
    <preserveFixedJoint>true</preserveFixedJoint>
    <!-- For compatibility with SDFormat < 4.4 -->
    <disableFixedJointLumping>true</disableFixedJointLumping>
  </gazebo>
  <gazebo reference="l_foot_front_ft_sensor">
    <preserveFixedJoint>true</preserveFixedJoint>
    <!-- For compatibility with SDFormat < 4.4 -->
    <disableFixedJointLumping>true</disableFixedJointLumping>
  </gazebo>
  <gazebo reference="l_foot_rear_ft_sensor">
    <preserveFixedJoint>true</preserveFixedJoint>
    <!-- For compatibility with SDFormat < 4.4 -->
    <disableFixedJointLumping>true</disableFixedJointLumping>
  </gazebo>
  <gazebo reference="l_foot_front">
    <collision>
      <surface>
        <bounce>
          <restitution_coefficient>0</restitution_coefficient>
          <threshold>100000</threshold>
        </bounce>
      </surface>
    </collision>
    <maxContacts>4</maxContacts>
    <kp>18000000</kp>
    <kd>100</kd>
    <maxVel>100</maxVel>
    <minDepth>0.0001</minDepth>
    <mu1>1</mu1>
    <mu2>1</mu2>
    <fdir1>0 0 0</fdir1>
  </gazebo>
  <gazebo reference="l_foot_rear">
    <collision>
      <surface>
        <bounce>
          <restitution_coefficient>0</restitution_coefficient>
          <threshold>100000</threshold>
        </bounce>
      </surface>
    </collision>
    <maxContacts>4</maxContacts>
    <kp>18000000</kp>
    <kd>100</kd>
    <maxVel>100</maxVel>
    <minDepth>0.0001</minDepth>
    <mu1>1</mu1>
    <mu2>1</mu2>
    <fdir1>0 0 0</fdir1>
  </gazebo>
  <gazebo>
    <plugin name="controlboard_left_leg" filename="libgazebo_yarp_controlboard.so">
      <yarpConfigurationFile>model://iRonCub-Mk3/iRonCub/conf/gazebo_icub_left_leg.ini</yarpConfigurationFile>
    </plugin>
  </gazebo>
  <gazebo reference="l_leg_ft_sensor">
    <preserveFixedJoint>true</preserveFixedJoint>
    <!-- For compatibility with SDFormat < 4.4 -->
    <disableFixedJointLumping>true</disableFixedJointLumping>
  </gazebo>
  <gazebo reference="r_leg_ft_sensor">
    <preserveFixedJoint>true</preserveFixedJoint>
    <!-- For compatibility with SDFormat < 4.4 -->
    <disableFixedJointLumping>true</disableFixedJointLumping>
  </gazebo>
  <gazebo reference="r_foot_front_ft_sensor">
    <preserveFixedJoint>true</preserveFixedJoint>
    <!-- For compatibility with SDFormat < 4.4 -->
    <disableFixedJointLumping>true</disableFixedJointLumping>
  </gazebo>
  <gazebo reference="r_foot_rear_ft_sensor">
    <preserveFixedJoint>true</preserveFixedJoint>
    <!-- For compatibility with SDFormat < 4.4 -->
    <disableFixedJointLumping>true</disableFixedJointLumping>
  </gazebo>
  <gazebo reference="r_foot_front">
    <collision>
      <surface>
        <bounce>
          <restitution_coefficient>0</restitution_coefficient>
          <threshold>100000</threshold>
        </bounce>
      </surface>
    </collision>
    <maxContacts>4</maxContacts>
    <kp>18000000</kp>
    <kd>100</kd>
    <maxVel>100</maxVel>
    <minDepth>0.0001</minDepth>
    <mu1>1</mu1>
    <mu2>1</mu2>
    <fdir1>0 0 0</fdir1>
  </gazebo>
  <gazebo reference="r_foot_rear">
    <collision>
      <surface>
        <bounce>
          <restitution_coefficient>0</restitution_coefficient>
          <threshold>100000</threshold>
        </bounce>
      </surface>
    </collision>
    <maxContacts>4</maxContacts>
    <kp>18000000</kp>
    <kd>100</kd>
    <maxVel>100</maxVel>
    <minDepth>0.0001</minDepth>
    <mu1>1</mu1>
    <mu2>1</mu2>
    <fdir1>0 0 0</fdir1>
  </gazebo>
  <gazebo reference="r_hip_pitch">
    <implicitSpringDamper>1</implicitSpringDamper>
  </gazebo>
  <gazebo reference="r_hip_roll">
    <implicitSpringDamper>1</implicitSpringDamper>
  </gazebo>
  <gazebo reference="r_hip_yaw">
    <implicitSpringDamper>1</implicitSpringDamper>
  </gazebo>
  <gazebo reference="r_knee">
    <implicitSpringDamper>1</implicitSpringDamper>
  </gazebo>
  <gazebo reference="r_ankle_pitch">
    <implicitSpringDamper>1</implicitSpringDamper>
  </gazebo>
  <gazebo reference="r_ankle_roll">
    <implicitSpringDamper>1</implicitSpringDamper>
  </gazebo>
  <gazebo reference="l_hip_pitch">
    <implicitSpringDamper>1</implicitSpringDamper>
  </gazebo>
  <gazebo reference="l_hip_roll">
    <implicitSpringDamper>1</implicitSpringDamper>
  </gazebo>
  <gazebo reference="l_hip_yaw">
    <implicitSpringDamper>1</implicitSpringDamper>
  </gazebo>
  <gazebo reference="l_knee">
    <implicitSpringDamper>1</implicitSpringDamper>
  </gazebo>
  <gazebo reference="l_ankle_pitch">
    <implicitSpringDamper>1</implicitSpringDamper>
  </gazebo>
  <gazebo reference="l_ankle_roll">
    <implicitSpringDamper>1</implicitSpringDamper>
  </gazebo>
  <gazebo reference="torso_pitch">
    <implicitSpringDamper>1</implicitSpringDamper>
  </gazebo>
  <gazebo reference="torso_roll">
    <implicitSpringDamper>1</implicitSpringDamper>
  </gazebo>
  <gazebo reference="torso_yaw">
    <implicitSpringDamper>1</implicitSpringDamper>
  </gazebo>
  <gazebo reference="r_shoulder_pitch">
    <implicitSpringDamper>1</implicitSpringDamper>
  </gazebo>
  <gazebo reference="r_shoulder_roll">
    <implicitSpringDamper>1</implicitSpringDamper>
  </gazebo>
  <gazebo reference="r_shoulder_yaw">
    <implicitSpringDamper>1</implicitSpringDamper>
  </gazebo>
  <gazebo reference="l_shoulder_pitch">
    <implicitSpringDamper>1</implicitSpringDamper>
  </gazebo>
  <gazebo reference="l_shoulder_roll">
    <implicitSpringDamper>1</implicitSpringDamper>
  </gazebo>
  <gazebo reference="l_shoulder_yaw">
    <implicitSpringDamper>1</implicitSpringDamper>
  </gazebo>
  <gazebo reference="l_elbow_turbine">
    <disableFixedJointLumping>true</disableFixedJointLumping>
  </gazebo>
  <gazebo reference="jetpack">
    <disableFixedJointLumping>true</disableFixedJointLumping>
  </gazebo>
  <gazebo reference="r_elbow_turbine">
    <disableFixedJointLumping>true</disableFixedJointLumping>
  </gazebo>
  <gazebo reference="neck_pitch">
    <implicitSpringDamper>1</implicitSpringDamper>
  </gazebo>
  <gazebo reference="neck_roll">
    <implicitSpringDamper>1</implicitSpringDamper>
  </gazebo>
  <gazebo reference="neck_yaw">
    <implicitSpringDamper>1</implicitSpringDamper>
  </gazebo>
  <gazebo reference="l_shoulder_pitch">
    <implicitSpringDamper>1</implicitSpringDamper>
  </gazebo>
  <gazebo reference="l_shoulder_roll">
    <implicitSpringDamper>1</implicitSpringDamper>
  </gazebo>
  <gazebo reference="l_shoulder_yaw">
    <implicitSpringDamper>1</implicitSpringDamper>
  </gazebo>
  <gazebo reference="l_elbow">
    <implicitSpringDamper>1</implicitSpringDamper>
  </gazebo>
  <gazebo reference="r_shoulder_pitch">
    <implicitSpringDamper>1</implicitSpringDamper>
  </gazebo>
  <gazebo reference="r_shoulder_roll">
    <implicitSpringDamper>1</implicitSpringDamper>
  </gazebo>
  <gazebo reference="r_shoulder_yaw">
    <implicitSpringDamper>1</implicitSpringDamper>
  </gazebo>
  <gazebo reference="r_elbow">
    <implicitSpringDamper>1</implicitSpringDamper>
  </gazebo>
  <gazebo>
    <plugin name="controlboard_right_arm_no_hand" filename="libgazebo_yarp_controlboard.so">
      <yarpConfigurationFile>model://iRonCub-Mk3/iRonCub/conf/gazebo_icub_right_arm_no_hand_for_no_hand_model.ini</yarpConfigurationFile>
      <initialConfiguration>-0.52 0.52 0 0.785 0 0 0.0</initialConfiguration>
    </plugin>
    <plugin name="controlboard_left_arm_no_hand" filename="libgazebo_yarp_controlboard.so">
      <yarpConfigurationFile>model://iRonCub-Mk3/iRonCub/conf/gazebo_icub_left_arm_no_hand_for_no_hand_model.ini</yarpConfigurationFile>
      <initialConfiguration>-0.52 0.52 0 0.785 0 0 0.0</initialConfiguration>
    </plugin>
    <plugin name="controlboard_right_leg" filename="libgazebo_yarp_controlboard.so">
      <yarpConfigurationFile>model://iRonCub-Mk3/iRonCub/conf/gazebo_icub_right_leg.ini</yarpConfigurationFile>
    </plugin>
    <plugin name="controlboard_torso" filename="libgazebo_yarp_controlboard.so">
      <yarpConfigurationFile>model://iRonCub-Mk3/iRonCub/conf/gazebo_icub_torso.ini</yarpConfigurationFile>
    </plugin>
    <plugin name="controlboard_head_without_eyes" filename="libgazebo_yarp_controlboard.so">
      <yarpConfigurationFile>model://iRonCub-Mk3/iRonCub/conf/gazebo_icub_head_without_eyes_V2_7.ini</yarpConfigurationFile>
    </plugin>
    <plugin name="jets-plugin" filename="libjets-plugin.so">
      <yarpConfigurationFile>model://iRonCub-Mk3/iRonCub/conf/jets.ini</yarpConfigurationFile>
    </plugin>
    <plugin name="basestate" filename="libgazebo_yarp_basestate.so">
      <yarpConfigurationFile>model://iRonCub-Mk3/iRonCub/conf/base.ini</yarpConfigurationFile>
    </plugin>
    <plugin name="robotinterface" filename="libgazebo_yarp_robotinterface.so">
      <yarpRobotInterfaceConfigurationFile>model://iRonCub-Mk3/iRonCub/conf/iRonCub.xml</yarpRobotInterfaceConfigurationFile>
    </plugin>
    <plugin name="apply_external_wrench" filename="libgazebo_yarp_externalwrench.so">
      <robotNamefromConfigFile>model://iCub/conf/gazebo_icub_robotname.ini</robotNamefromConfigFile>
    </plugin>
  </gazebo>
  <gazebo>
    <pose>0.000000 0.000000 0.640000 0.000000 0.000000 0.000000</pose>
  </gazebo>
  <gazebo reference="l_arm_ft_sensor">
    <sensor name="l_arm_ft" type="force_torque">
      <always_on>1</always_on>
      <update_rate>100</update_rate>
      <force_torque>
        <frame>sensor</frame>
        <measure_direction>child_to_parent</measure_direction>
      </force_torque>
      <pose>0 0 0 3.14159 2.77556e-17 -1.5708 </pose>
      <plugin name="left_arm_ft_plugin" filename="libgazebo_yarp_forcetorque.so">
        <yarpConfigurationFile>model://iRonCub-Mk3/iRonCub/conf/FT/gazebo_icub_left_arm_ft.ini</yarpConfigurationFile>
      </plugin>
    </sensor>
  </gazebo>
  <sensor name="l_arm_ft" type="force_torque">
    <parent joint="l_arm_ft_sensor"/>
    <force_torque>
      <frame>sensor</frame>
      <measure_direction>child_to_parent</measure_direction>
    </force_torque>
    <origin rpy="3.14159 2.77556e-17 -1.5708 " xyz="0 0 0"/>
  </sensor>
  <gazebo reference="l_foot_front_ft_sensor">
    <sensor name="l_foot_front_ft" type="force_torque">
      <always_on>1</always_on>
      <update_rate>100</update_rate>
      <force_torque>
        <frame>sensor</frame>
        <measure_direction>parent_to_child</measure_direction>
      </force_torque>
      <pose>4.16334e-17 2.77556e-17 0.0223 -3.08992e-16 -2.75863e-16 -2.0944 </pose>
      <plugin name="left_foot_front_ft_plugin" filename="libgazebo_yarp_forcetorque.so">
        <yarpConfigurationFile>model://iRonCub-Mk3/iRonCub/conf/FT/gazebo_icub_left_foot_front_ft.ini</yarpConfigurationFile>
      </plugin>
    </sensor>
  </gazebo>
  <sensor name="l_foot_front_ft" type="force_torque">
    <parent joint="l_foot_front_ft_sensor"/>
    <force_torque>
      <frame>sensor</frame>
      <measure_direction>parent_to_child</measure_direction>
    </force_torque>
    <origin rpy="-3.08992e-16 -2.75863e-16 -2.0944 " xyz="4.16334e-17 2.77556e-17 0.0223"/>
  </sensor>
  <gazebo reference="l_foot_rear_ft_sensor">
    <sensor name="l_foot_rear_ft" type="force_torque">
      <always_on>1</always_on>
      <update_rate>100</update_rate>
      <force_torque>
        <frame>sensor</frame>
        <measure_direction>parent_to_child</measure_direction>
      </force_torque>
      <pose>3.46945e-18 0 0.0223 2.46119e-16 5.72039e-17 -2.0944 </pose>
      <plugin name="left_foot_rear_ft_plugin" filename="libgazebo_yarp_forcetorque.so">
        <yarpConfigurationFile>model://iRonCub-Mk3/iRonCub/conf/FT/gazebo_icub_left_foot_rear_ft.ini</yarpConfigurationFile>
      </plugin>
    </sensor>
  </gazebo>
  <sensor name="l_foot_rear_ft" type="force_torque">
    <parent joint="l_foot_rear_ft_sensor"/>
    <force_torque>
      <frame>sensor</frame>
      <measure_direction>parent_to_child</measure_direction>
    </force_torque>
    <origin rpy="2.46119e-16 5.72039e-17 -2.0944 " xyz="3.46945e-18 0 0.0223"/>
  </sensor>
  <gazebo reference="l_jet_ft_sensor">
    <sensor name="l_jet_ft" type="force_torque">
      <always_on>1</always_on>
      <update_rate>100</update_rate>
      <force_torque>
        <frame>sensor</frame>
        <measure_direction>child_to_parent</measure_direction>
      </force_torque>
      <pose>-0.000289476 0.0945 -0.171052 4.01903e-16 -5.55112e-17 -1.5708 </pose>
      <plugin name="left_jet_ft_plugin" filename="libgazebo_yarp_forcetorque.so">
        <yarpConfigurationFile>model://iRonCub-Mk3/iRonCub/conf/FT/gazebo_icub_left_jet_ft.ini</yarpConfigurationFile>
      </plugin>
    </sensor>
  </gazebo>
  <sensor name="l_jet_ft" type="force_torque">
    <parent joint="l_jet_ft_sensor"/>
    <force_torque>
      <frame>sensor</frame>
      <measure_direction>child_to_parent</measure_direction>
    </force_torque>
    <origin rpy="4.01903e-16 -5.55112e-17 -1.5708 " xyz="-0.000289476 0.0945 -0.171052"/>
  </sensor>
  <gazebo reference="r_arm_ft_sensor">
    <sensor name="r_arm_ft" type="force_torque">
      <always_on>1</always_on>
      <update_rate>100</update_rate>
      <force_torque>
        <frame>sensor</frame>
        <measure_direction>child_to_parent</measure_direction>
      </force_torque>
      <pose>0 0 0 -3.14159 -2.77556e-17 1.5708 </pose>
      <plugin name="right_arm_ft_plugin" filename="libgazebo_yarp_forcetorque.so">
        <yarpConfigurationFile>model://iRonCub-Mk3/iRonCub/conf/FT/gazebo_icub_right_arm_ft.ini</yarpConfigurationFile>
      </plugin>
    </sensor>
  </gazebo>
  <sensor name="r_arm_ft" type="force_torque">
    <parent joint="r_arm_ft_sensor"/>
    <force_torque>
      <frame>sensor</frame>
      <measure_direction>child_to_parent</measure_direction>
    </force_torque>
    <origin rpy="-3.14159 -2.77556e-17 1.5708 " xyz="0 0 0"/>
  </sensor>
  <gazebo reference="r_foot_front_ft_sensor">
    <sensor name="r_foot_front_ft" type="force_torque">
      <always_on>1</always_on>
      <update_rate>100</update_rate>
      <force_torque>
        <frame>sensor</frame>
        <measure_direction>parent_to_child</measure_direction>
      </force_torque>
      <pose>2.77556e-17 -1.38778e-17 0.0223 3.29604e-14 1.89963e-14 -2.0944 </pose>
      <plugin name="right_foot_front_ft_sensor_plugin" filename="libgazebo_yarp_forcetorque.so">
        <yarpConfigurationFile>model://iRonCub-Mk3/iRonCub/conf/FT/gazebo_icub_right_foot_front_ft.ini</yarpConfigurationFile>
      </plugin>
    </sensor>
  </gazebo>
  <sensor name="r_foot_front_ft" type="force_torque">
    <parent joint="r_foot_front_ft_sensor"/>
    <force_torque>
      <frame>sensor</frame>
      <measure_direction>parent_to_child</measure_direction>
    </force_torque>
    <origin rpy="3.29604e-14 1.89963e-14 -2.0944 " xyz="2.77556e-17 -1.38778e-17 0.0223"/>
  </sensor>
  <gazebo reference="r_foot_rear_ft_sensor">
    <sensor name="r_foot_rear_ft" type="force_torque">
      <always_on>1</always_on>
      <update_rate>100</update_rate>
      <force_torque>
        <frame>sensor</frame>
        <measure_direction>parent_to_child</measure_direction>
      </force_torque>
      <pose>-1.73472e-18 1.38778e-17 0.0223 3.35155e-14 1.93294e-14 -2.0944 </pose>
      <plugin name="right_foot_rear_ft_sensor_plugin" filename="libgazebo_yarp_forcetorque.so">
        <yarpConfigurationFile>model://iRonCub-Mk3/iRonCub/conf/FT/gazebo_icub_right_foot_rear_ft.ini</yarpConfigurationFile>
      </plugin>
    </sensor>
  </gazebo>
  <sensor name="r_foot_rear_ft" type="force_torque">
    <parent joint="r_foot_rear_ft_sensor"/>
    <force_torque>
      <frame>sensor</frame>
      <measure_direction>parent_to_child</measure_direction>
    </force_torque>
    <origin rpy="3.35155e-14 1.93294e-14 -2.0944 " xyz="-1.73472e-18 1.38778e-17 0.0223"/>
  </sensor>
  <gazebo reference="r_jet_ft_sensor">
    <sensor name="r_jet_ft" type="force_torque">
      <always_on>1</always_on>
      <update_rate>100</update_rate>
      <force_torque>
        <frame>sensor</frame>
        <measure_direction>child_to_parent</measure_direction>
      </force_torque>
      <pose>-0.000289476 -0.095 -0.171052 -3.35352e-16 -0 1.5708 </pose>
      <plugin name="right_jet_ft_plugin" filename="libgazebo_yarp_forcetorque.so">
        <yarpConfigurationFile>model://iRonCub-Mk3/iRonCub/conf/FT/gazebo_icub_right_jet_ft.ini</yarpConfigurationFile>
      </plugin>
    </sensor>
  </gazebo>
  <sensor name="r_jet_ft" type="force_torque">
    <parent joint="r_jet_ft_sensor"/>
    <force_torque>
      <frame>sensor</frame>
      <measure_direction>child_to_parent</measure_direction>
    </force_torque>
    <origin rpy="-3.35352e-16 -0 1.5708 " xyz="-0.000289476 -0.095 -0.171052"/>
  </sensor>
  <gazebo reference="head">
    <sensor name="head_imu" type="imu">
      <always_on>1</always_on>
      <update_rate>100.000000</update_rate>
      <pose>0.0035 0.0055 0.101334 3.14159 1.22465e-16 -1.5708 </pose>
      <plugin name="iCub_yarp_gazebo_plugin_IMU" filename="libgazebo_yarp_imu.so">
        <yarpConfigurationFile>model://iRonCub-Mk3/iRonCub/conf/gazebo_icub_inertial.ini</yarpConfigurationFile>
      </plugin>
    </sensor>
  </gazebo>
  <sensor name="head_imu" type="accelerometer">
    <parent link="head"/>
    <origin rpy="3.14159 1.22465e-16 -1.5708 " xyz="0.0035 0.0055 0.101334"/>
  </sensor>
  <gazebo reference="chest">
    <sensor name="chest_imu" type="imu">
      <always_on>1</always_on>
      <update_rate>100.000000</update_rate>
      <pose>0.100122 0.00772565 0.081506 -1.5708 -1.56982 -1.5708 </pose>
      <plugin name="chest_plugin_IMU" filename="libgazebo_yarp_imu.so">
        <yarpConfigurationFile>model://iRonCub-Mk3/iRonCub/conf/gazebo_icub_xsens_inertial.ini</yarpConfigurationFile>
      </plugin>
    </sensor>
  </gazebo>
  <sensor name="chest_imu" type="accelerometer">
    <parent link="chest"/>
    <origin rpy="-1.5708 -1.56982 -1.5708 " xyz="0.100122 0.00772565 0.081506"/>
  </sensor>
</robot>
