<?xml version="1.0" encoding="utf-8"?>
<robot name="passive_walker">
  <link name="root">
    <inertial>
      <origin xyz="0.0 0.0 0.0" rpy="0.0 0.0 0.0"/>
      <mass value="0.5"/>
      <inertia ixx="0.037083333333333336" ixy="0.0" ixz="0.0" iyy="0.012083333333333335" iyz="0.0" izz="0.02833333333333334"/>
    </inertial>
    <visual name="root_visual">
      <origin xyz="0.0 0.0 0.0" rpy="0.0 0.0 0.0"/>
      <geometry>
        <box size="0.2 0.8 0.5"/>
      </geometry>
    </visual>
    <collision name="root_collision">
      <origin xyz="0.0 0.0 0.0" rpy="0.0 0.0 0.0"/>
      <geometry>
        <box size="0.2 0.8 0.5"/>
      </geometry>
    </collision>
  </link>
  <link name="left_leg">
    <inertial>
      <origin xyz="0.0 0.0 -0.75" rpy="0.0 0.0 0.0"/>
      <mass value="0.2"/>
      <inertia ixx="0.037680000000000005" ixy="0.0" ixz="0.0" iyy="0.037680000000000005" iyz="0.0" izz="0.00036"/>
    </inertial>
    <visual name="left_leg_visual">
      <origin xyz="0.0 0.0 -0.75" rpy="0.0 0.0 0.0"/>
      <geometry>
        <cylinder radius="0.06" length="1.5"/>
      </geometry>
    </visual>
    <collision name="left_leg_collision">
      <origin xyz="0.0 0.0 -0.75" rpy="0.0 0.0 0.0"/>
      <geometry>
        <cylinder radius="0.06" length="1.5"/>
      </geometry>
    </collision>
  </link>
  <link name="right_leg">
    <inertial>
      <origin xyz="0.0 0.0 -0.75" rpy="0.0 0.0 0.0"/>
      <mass value="0.2"/>
      <inertia ixx="0.037680000000000005" ixy="0.0" ixz="0.0" iyy="0.037680000000000005" iyz="0.0" izz="0.00036"/>
    </inertial>
    <visual name="right_leg_visual">
      <origin xyz="0.0 0.0 -0.75" rpy="0.0 0.0 0.0"/>
      <geometry>
        <cylinder radius="0.06" length="1.5"/>
      </geometry>
    </visual>
    <collision name="right_leg_collision">
      <origin xyz="0.0 0.0 -0.75" rpy="0.0 0.0 0.0"/>
      <geometry>
        <cylinder radius="0.06" length="1.5"/>
      </geometry>
    </collision>
  </link>
  <link name="left_foot">
    <inertial>
      <origin xyz="0.0 0.0 0.0" rpy="0.0 0.0 0.0"/>
      <mass value="3.0"/>
      <inertia ixx="0.01" ixy="2.5547406570745716e-05" ixz="0.0006704452847879228" iyy="0.01" iyz="-0.021354195549583566" izz="0.01"/>
    </inertial>
    <visual name="left_foot_visual">
      <origin xyz="0.0 0.0 0.0" rpy="0.0 0.0 0.0"/>
      <geometry>
        <mesh filename="../../meshes/foot_2.obj" scale="0.3 0.3 0.3"/>
      </geometry>
    </visual>
    <collision name="left_foot_collision">
      <origin xyz="0.0 0.0 0.0" rpy="0.0 0.0 0.0"/>
      <geometry>
        <mesh filename="../../meshes/foot_2.obj" scale="0.3 0.3 0.3"/>
      </geometry>
    </collision>
  </link>
  <link name="right_foot">
    <inertial>
      <origin xyz="0.0 0.0 0.0" rpy="0.0 0.0 0.0"/>
      <mass value="0.5"/>
      <inertia ixx="0.37910792427372064" ixy="2.5547406570745716e-05" ixz="0.0006704452847879228" iyy="0.788029998387879" iyz="-0.021354195549583566" izz="0.4459529083989767"/>
    </inertial>
    <visual name="right_foot_visual">
      <origin xyz="0.0 0.0 0.0" rpy="0.0 0.0 0.0"/>
      <geometry>
        <mesh filename="../../meshes/foot_2.obj" scale="0.3 0.3 0.3"/>
      </geometry>
    </visual>
    <collision name="right_foot_collision">
      <origin xyz="0.0 0.0 0.0" rpy="0.0 0.0 0.0"/>
      <geometry>
        <mesh filename="../../meshes/foot_2.obj" scale="0.3 0.3 0.3"/>
      </geometry>
    </collision>
  </link>
  <joint name="left_hip" type="revolute">
    <origin xyz="0.0 -0.47 0.0" rpy="0.0 0.0 0.0"/>
    <parent link="root"/>
    <child link="left_leg"/>
    <axis xyz="0.0 1.0 0.0"/>
    <dynamics damping="0.0" friction="0.0001"/>
    <limit effort="3.4028235e+38" velocity="3.4028235e+38" lower="-0.1096622711232151" upper="0.1096622711232151"/>
  </joint>
  <joint name="right_hip" type="revolute">
    <origin xyz="0.0 0.47 0.0" rpy="0.0 0.0 0.0"/>
    <parent link="root"/>
    <child link="right_leg"/>
    <axis xyz="0.0 1.0 0.0"/>
    <dynamics damping="2.0" friction="0.0001"/>
    <limit effort="1e+9" velocity="1e+9" lower="-0.5235987755982988" upper="0.5235987755982988"/>
  </joint>
  <joint name="left_ankle" type="fixed">
    <origin xyz="0.0 -0.2 -1.5" rpy="1.5707963267948963 0.0 0.0"/>
    <parent link="left_leg"/>
    <child link="left_foot"/>
  </joint>
  <joint name="right_ankle" type="fixed">
    <origin xyz="0.0 0.2 -1.5" rpy="1.5707963267948963 0.0 3.141592653589793"/>
    <parent link="right_leg"/>
    <child link="right_foot"/>
  </joint>
  <gazebo reference="left_ankle">
    <preserveFixedJoint>true</preserveFixedJoint>
    <disableFixedJointLumping>true</disableFixedJointLumping>
  </gazebo>
  <gazebo reference="right_ankle">
    <preserveFixedJoint>true</preserveFixedJoint>
    <disableFixedJointLumping>true</disableFixedJointLumping>
  </gazebo>
</robot>